2019-06-13 21:55:16,186 - telegram.ext.dispatcher - ERROR - An uncaught error was raised while processing the update
Traceback (most recent call last):
  File "/usr/local/lib/python3.7/site-packages/telegram/ext/dispatcher.py", line 279, in process_update
    handler.handle_update(update, self)
  File "/usr/local/lib/python3.7/site-packages/telegram/ext/commandhandler.py", line 173, in handle_update
    return self.callback(dispatcher.bot, update, **optional_args)
  File "/Users/logan/PycharmProjects/MonopolyTelegramBot/telegram_interaction.py", line 200, in startgame_handler
    send_infos(bot, chat_id, game, pending_players)
  File "/Users/logan/PycharmProjects/MonopolyTelegramBot/telegram_interaction.py", line 53, in send_infos
    send_info(bot, chat_id, game, user_id)
  File "/Users/logan/PycharmProjects/MonopolyTelegramBot/telegram_interaction.py", line 46, in send_info
    cards = player.get_out_free_cards()
TypeError: 'int' object is not callable
2019-06-13 21:56:04,675 - telegram.ext.updater - INFO - Received signal 2 (SIGINT), stopping...
2019-06-13 22:11:02,093 - telegram.ext.updater - INFO - Received signal 2 (SIGINT), stopping...
