2019-06-13 21:55:16,186 - telegram.ext.dispatcher - ERROR - An uncaught error was raised while processing the update
Traceback (most recent call last):
  File "/usr/local/lib/python3.7/site-packages/telegram/ext/dispatcher.py", line 279, in process_update
    handler.handle_update(update, self)
  File "/usr/local/lib/python3.7/site-packages/telegram/ext/commandhandler.py", line 173, in handle_update
    return self.callback(dispatcher.bot, update, **optional_args)
  File "/Users/logan/PycharmProjects/MonopolyTelegramBot/telegram_interaction.py", line 200, in startgame_handler
    send_infos(bot, chat_id, game, pending_players)
  File "/Users/logan/PycharmProjects/MonopolyTelegramBot/telegram_interaction.py", line 53, in send_infos
    send_info(bot, chat_id, game, user_id)
  File "/Users/logan/PycharmProjects/MonopolyTelegramBot/telegram_interaction.py", line 46, in send_info
    cards = player.get_out_free_cards()
TypeError: 'int' object is not callable
2019-06-13 21:56:04,675 - telegram.ext.updater - INFO - Received signal 2 (SIGINT), stopping...
2019-06-13 22:11:02,093 - telegram.ext.updater - INFO - Received signal 2 (SIGINT), stopping...
2019-06-14 17:07:47,394 - telegram.ext.updater - INFO - Received signal 2 (SIGINT), stopping...
2019-06-14 17:08:08,670 - telegram.ext.dispatcher - ERROR - An uncaught error was raised while processing the update
Traceback (most recent call last):
  File "/usr/local/lib/python3.7/site-packages/telegram/ext/dispatcher.py", line 279, in process_update
    handler.handle_update(update, self)
  File "/usr/local/lib/python3.7/site-packages/telegram/ext/commandhandler.py", line 173, in handle_update
    return self.callback(dispatcher.bot, update, **optional_args)
  File "/Users/logan/PycharmProjects/MonopolyTelegramBot/telegram_interaction.py", line 238, in roll_handler
    bot.send_message(chat_id=chat_id, text=winner.get_name() + " has won!")
AttributeError: 'tuple' object has no attribute 'get_name'
2019-06-14 17:08:44,337 - telegram.ext.updater - INFO - Received signal 2 (SIGINT), stopping...
2019-06-14 17:48:55,340 - telegram.ext.updater - INFO - Received signal 2 (SIGINT), stopping...
2019-06-14 17:50:45,940 - telegram.ext.updater - INFO - Received signal 2 (SIGINT), stopping...
2019-06-14 22:04:51,529 - telegram.vendor.ptb_urllib3.urllib3.connectionpool - WARNING - Retrying (Retry(total=2, connect=None, read=None, redirect=None)) after connection broken by 'NewConnectionError('<telegram.vendor.ptb_urllib3.urllib3.connection.VerifiedHTTPSConnection object at 0x10953fda0>: Failed to establish a new connection: [Errno 8] nodename nor servname provided, or not known')': /bot854076226:AAGBGAeMq3le6mU2FpKcONa2b88D6A2-SzU/getUpdates
2019-06-14 22:04:51,532 - telegram.vendor.ptb_urllib3.urllib3.connectionpool - WARNING - Retrying (Retry(total=1, connect=None, read=None, redirect=None)) after connection broken by 'NewConnectionError('<telegram.vendor.ptb_urllib3.urllib3.connection.VerifiedHTTPSConnection object at 0x10953ff60>: Failed to establish a new connection: [Errno 8] nodename nor servname provided, or not known')': /bot854076226:AAGBGAeMq3le6mU2FpKcONa2b88D6A2-SzU/getUpdates
2019-06-14 22:04:51,535 - telegram.vendor.ptb_urllib3.urllib3.connectionpool - WARNING - Retrying (Retry(total=0, connect=None, read=None, redirect=None)) after connection broken by 'NewConnectionError('<telegram.vendor.ptb_urllib3.urllib3.connection.VerifiedHTTPSConnection object at 0x10953fe48>: Failed to establish a new connection: [Errno 8] nodename nor servname provided, or not known')': /bot854076226:AAGBGAeMq3le6mU2FpKcONa2b88D6A2-SzU/getUpdates
2019-06-14 22:04:51,538 - telegram.ext.updater - ERROR - Error while getting Updates: urllib3 HTTPError HTTPSConnectionPool(host='api.telegram.org', port=443): Max retries exceeded with url: /bot854076226:AAGBGAeMq3le6mU2FpKcONa2b88D6A2-SzU/getUpdates (Caused by NewConnectionError('<telegram.vendor.ptb_urllib3.urllib3.connection.VerifiedHTTPSConnection object at 0x10953fcc0>: Failed to establish a new connection: [Errno 8] nodename nor servname provided, or not known'))
2019-06-14 22:04:51,539 - __main__ - WARNING - Telegram Error! urllib3 HTTPError HTTPSConnectionPool(host='api.telegram.org', port=443): Max retries exceeded with url: /bot854076226:AAGBGAeMq3le6mU2FpKcONa2b88D6A2-SzU/getUpdates (Caused by NewConnectionError('<telegram.vendor.ptb_urllib3.urllib3.connection.VerifiedHTTPSConnection object at 0x10953fcc0>: Failed to establish a new connection: [Errno 8] nodename nor servname provided, or not known')) caused by this update: None
2019-06-14 22:04:52,543 - telegram.vendor.ptb_urllib3.urllib3.connectionpool - WARNING - Retrying (Retry(total=2, connect=None, read=None, redirect=None)) after connection broken by 'NewConnectionError('<telegram.vendor.ptb_urllib3.urllib3.connection.VerifiedHTTPSConnection object at 0x10953f9b0>: Failed to establish a new connection: [Errno 8] nodename nor servname provided, or not known')': /bot854076226:AAGBGAeMq3le6mU2FpKcONa2b88D6A2-SzU/getUpdates
2019-06-14 22:04:52,545 - telegram.vendor.ptb_urllib3.urllib3.connectionpool - WARNING - Retrying (Retry(total=1, connect=None, read=None, redirect=None)) after connection broken by 'NewConnectionError('<telegram.vendor.ptb_urllib3.urllib3.connection.VerifiedHTTPSConnection object at 0x10953f9e8>: Failed to establish a new connection: [Errno 8] nodename nor servname provided, or not known')': /bot854076226:AAGBGAeMq3le6mU2FpKcONa2b88D6A2-SzU/getUpdates
2019-06-14 22:04:52,546 - telegram.vendor.ptb_urllib3.urllib3.connectionpool - WARNING - Retrying (Retry(total=0, connect=None, read=None, redirect=None)) after connection broken by 'NewConnectionError('<telegram.vendor.ptb_urllib3.urllib3.connection.VerifiedHTTPSConnection object at 0x10953f358>: Failed to establish a new connection: [Errno 8] nodename nor servname provided, or not known')': /bot854076226:AAGBGAeMq3le6mU2FpKcONa2b88D6A2-SzU/getUpdates
2019-06-14 22:04:52,547 - telegram.ext.updater - ERROR - Error while getting Updates: urllib3 HTTPError HTTPSConnectionPool(host='api.telegram.org', port=443): Max retries exceeded with url: /bot854076226:AAGBGAeMq3le6mU2FpKcONa2b88D6A2-SzU/getUpdates (Caused by NewConnectionError('<telegram.vendor.ptb_urllib3.urllib3.connection.VerifiedHTTPSConnection object at 0x10953f5f8>: Failed to establish a new connection: [Errno 8] nodename nor servname provided, or not known'))
2019-06-14 22:04:52,547 - __main__ - WARNING - Telegram Error! urllib3 HTTPError HTTPSConnectionPool(host='api.telegram.org', port=443): Max retries exceeded with url: /bot854076226:AAGBGAeMq3le6mU2FpKcONa2b88D6A2-SzU/getUpdates (Caused by NewConnectionError('<telegram.vendor.ptb_urllib3.urllib3.connection.VerifiedHTTPSConnection object at 0x10953f5f8>: Failed to establish a new connection: [Errno 8] nodename nor servname provided, or not known')) caused by this update: None
2019-06-14 22:05:08,290 - telegram.ext.updater - INFO - Received signal 2 (SIGINT), stopping...
2019-06-14 22:05:39,021 - telegram.ext.dispatcher - ERROR - An uncaught error was raised while processing the update
Traceback (most recent call last):
  File "/usr/local/lib/python3.7/site-packages/telegram/ext/dispatcher.py", line 279, in process_update
    handler.handle_update(update, self)
  File "/usr/local/lib/python3.7/site-packages/telegram/ext/commandhandler.py", line 173, in handle_update
    return self.callback(dispatcher.bot, update, **optional_args)
TypeError: purchase_property_handler() got an unexpected keyword argument 'args'
2019-06-14 22:08:01,131 - telegram.ext.updater - INFO - Received signal 2 (SIGINT), stopping...
2019-06-14 22:08:40,843 - telegram.ext.dispatcher - ERROR - An uncaught error was raised while processing the update
Traceback (most recent call last):
  File "/usr/local/lib/python3.7/site-packages/telegram/ext/dispatcher.py", line 279, in process_update
    handler.handle_update(update, self)
  File "/usr/local/lib/python3.7/site-packages/telegram/ext/commandhandler.py", line 173, in handle_update
    return self.callback(dispatcher.bot, update, **optional_args)
  File "/Users/logan/PycharmProjects/MonopolyTelegramBot/telegram_interaction.py", line 316, in end_turn_handler
    game.end_turn(user_id)
  File "/Users/logan/PycharmProjects/MonopolyTelegramBot/monopoly.py", line 381, in end_turn
    self.players.get(str(self.turn)).get_name())
AttributeError: 'NoneType' object has no attribute 'get_name'
2019-06-14 22:08:50,449 - telegram.ext.updater - INFO - Received signal 2 (SIGINT), stopping...
2019-06-14 22:09:49,793 - telegram.ext.dispatcher - ERROR - An uncaught error was raised while processing the update
Traceback (most recent call last):
  File "/usr/local/lib/python3.7/site-packages/telegram/ext/dispatcher.py", line 279, in process_update
    handler.handle_update(update, self)
  File "/usr/local/lib/python3.7/site-packages/telegram/ext/commandhandler.py", line 173, in handle_update
    return self.callback(dispatcher.bot, update, **optional_args)
  File "/Users/logan/PycharmProjects/MonopolyTelegramBot/telegram_interaction.py", line 316, in end_turn_handler
    game.end_turn(user_id)
  File "/Users/logan/PycharmProjects/MonopolyTelegramBot/monopoly.py", line 381, in end_turn
    self.players.get(self.turn).get_name())
AttributeError: 'NoneType' object has no attribute 'get_name'
2019-06-14 22:10:43,725 - telegram.ext.updater - INFO - Received signal 2 (SIGINT), stopping...
2019-06-14 22:11:23,981 - telegram.ext.dispatcher - ERROR - An uncaught error was raised while processing the update
Traceback (most recent call last):
  File "/usr/local/lib/python3.7/site-packages/telegram/ext/dispatcher.py", line 279, in process_update
    handler.handle_update(update, self)
  File "/usr/local/lib/python3.7/site-packages/telegram/ext/commandhandler.py", line 173, in handle_update
    return self.callback(dispatcher.bot, update, **optional_args)
  File "/Users/logan/PycharmProjects/MonopolyTelegramBot/telegram_interaction.py", line 242, in roll_handler
    game.roll_dice(user_id)
  File "/Users/logan/PycharmProjects/MonopolyTelegramBot/monopoly.py", line 1022, in roll_dice
    self.enact_roll_result(player)
  File "/Users/logan/PycharmProjects/MonopolyTelegramBot/monopoly.py", line 906, in enact_roll_result
    self.cc_result(player)
  File "/Users/logan/PycharmProjects/MonopolyTelegramBot/monopoly.py", line 839, in cc_result
    player.set_turns_in_jail(3)
AttributeError: 'Player' object has no attribute 'set_turns_in_jail'
2019-06-14 22:13:12,081 - telegram.ext.dispatcher - ERROR - An uncaught error was raised while processing the update
Traceback (most recent call last):
  File "/usr/local/lib/python3.7/site-packages/telegram/ext/dispatcher.py", line 279, in process_update
    handler.handle_update(update, self)
  File "/usr/local/lib/python3.7/site-packages/telegram/ext/commandhandler.py", line 173, in handle_update
    return self.callback(dispatcher.bot, update, **optional_args)
  File "/Users/logan/PycharmProjects/MonopolyTelegramBot/telegram_interaction.py", line 143, in listplayers_handler
    num_cards_str = str(len(game.get_player(user_id).get_hand()))
AttributeError: 'Game' object has no attribute 'get_player'
2019-06-14 22:14:45,615 - telegram.ext.updater - INFO - Received signal 2 (SIGINT), stopping...
2019-06-15 00:14:02,480 - telegram.ext.dispatcher - ERROR - An uncaught error was raised while processing the update
Traceback (most recent call last):
  File "/usr/local/lib/python3.7/site-packages/telegram/ext/dispatcher.py", line 279, in process_update
    handler.handle_update(update, self)
  File "/usr/local/lib/python3.7/site-packages/telegram/ext/commandhandler.py", line 173, in handle_update
    return self.callback(dispatcher.bot, update, **optional_args)
  File "/Users/logan/PycharmProjects/MonopolyTelegramBot/telegram_interaction.py", line 241, in roll_handler
    game.roll_dice(user_id)
  File "/Users/logan/PycharmProjects/MonopolyTelegramBot/monopoly.py", line 1022, in roll_dice
    self.enact_roll_result(player)
  File "/Users/logan/PycharmProjects/MonopolyTelegramBot/monopoly.py", line 930, in enact_roll_result
    rent = property.get_rent_cost()
AttributeError: 'Property' object has no attribute 'get_rent_cost'
2019-06-15 00:14:53,081 - telegram.ext.updater - INFO - Received signal 2 (SIGINT), stopping...
2019-06-15 00:34:10,046 - telegram.ext.dispatcher - ERROR - An uncaught error was raised while processing the update
Traceback (most recent call last):
  File "/usr/local/lib/python3.7/site-packages/telegram/ext/dispatcher.py", line 279, in process_update
    handler.handle_update(update, self)
  File "/usr/local/lib/python3.7/site-packages/telegram/ext/commandhandler.py", line 173, in handle_update
    return self.callback(dispatcher.bot, update, **optional_args)
  File "/Users/logan/PycharmProjects/MonopolyTelegramBot/telegram_interaction.py", line 396, in add_to_trade_handler
    game.add_to_trade(user_id, int(args[0]), int(args[1]), int(args[2]))
  File "/Users/logan/PycharmProjects/MonopolyTelegramBot/monopoly.py", line 516, in add_to_trade
    self.send_message("That property is already in the trade!")
TypeError: 'tuple' object does not support item assignment
2019-06-15 00:34:41,668 - telegram.ext.dispatcher - ERROR - An uncaught error was raised while processing the update
Traceback (most recent call last):
  File "/usr/local/lib/python3.7/site-packages/telegram/ext/dispatcher.py", line 279, in process_update
    handler.handle_update(update, self)
  File "/usr/local/lib/python3.7/site-packages/telegram/ext/commandhandler.py", line 173, in handle_update
    return self.callback(dispatcher.bot, update, **optional_args)
  File "/Users/logan/PycharmProjects/MonopolyTelegramBot/telegram_interaction.py", line 411, in remove_from_trade_handler
    game.remove_from_trade(user_id, int(args[0]), int(args[1]), int(args[2]))
  File "/Users/logan/PycharmProjects/MonopolyTelegramBot/monopoly.py", line 573, in remove_from_trade
    property = player.get_property_by_id(prop)
TypeError: 'tuple' object does not support item assignment
2019-06-15 00:46:37,607 - telegram.ext.updater - INFO - Received signal 2 (SIGINT), stopping...
2019-06-15 13:15:46,056 - telegram.ext.updater - INFO - Received signal 2 (SIGINT), stopping...
2019-06-15 13:22:53,515 - telegram.ext.dispatcher - ERROR - An uncaught error was raised while processing the update
Traceback (most recent call last):
  File "/usr/local/lib/python3.7/site-packages/telegram/ext/dispatcher.py", line 279, in process_update
    handler.handle_update(update, self)
  File "/usr/local/lib/python3.7/site-packages/telegram/ext/commandhandler.py", line 173, in handle_update
    return self.callback(dispatcher.bot, update, **optional_args)
  File "/Users/logan/PycharmProjects/MonopolyTelegramBot/telegram_interaction.py", line 241, in roll_handler
    game.roll_dice(user_id)
  File "/Users/logan/PycharmProjects/MonopolyTelegramBot/monopoly.py", line 1047, in roll_dice
    self.send_message("You passed Go and collected $200!")
  File "/Users/logan/PycharmProjects/MonopolyTelegramBot/monopoly.py", line 923, in enact_roll_result
    self.cc_result(player)
  File "/Users/logan/PycharmProjects/MonopolyTelegramBot/monopoly.py", line 866, in cc_result
    self.pending_payments.appned((self.players[id], player, 10))
AttributeError: 'list' object has no attribute 'appned'
2019-06-15 13:32:02,681 - telegram.ext.updater - INFO - Received signal 2 (SIGINT), stopping...
2019-06-15 13:33:36,969 - telegram.ext.dispatcher - ERROR - An uncaught error was raised while processing the update
Traceback (most recent call last):
  File "/usr/local/lib/python3.7/site-packages/telegram/ext/dispatcher.py", line 279, in process_update
    handler.handle_update(update, self)
  File "/usr/local/lib/python3.7/site-packages/telegram/ext/commandhandler.py", line 173, in handle_update
    return self.callback(dispatcher.bot, update, **optional_args)
  File "/Users/logan/PycharmProjects/MonopolyTelegramBot/telegram_interaction.py", line 471, in assets_handler
    send_info(bot, chat_id, game, user_id)
  File "/Users/logan/PycharmProjects/MonopolyTelegramBot/telegram_interaction.py", line 44, in send_info
    props = player.get_properties_str()
  File "/Users/logan/PycharmProjects/MonopolyTelegramBot/monopoly.py", line 83, in get_properties_str
    text += "(" + str(count) + ") " + p.get_name() + " : " + p.get_color() + "\n"
AttributeError: 'OtherProperty' object has no attribute 'get_color'
2019-06-15 13:34:15,670 - telegram.ext.dispatcher - ERROR - An uncaught error was raised while processing the update
Traceback (most recent call last):
  File "/usr/local/lib/python3.7/site-packages/telegram/ext/dispatcher.py", line 279, in process_update
    handler.handle_update(update, self)
  File "/usr/local/lib/python3.7/site-packages/telegram/ext/commandhandler.py", line 173, in handle_update
    return self.callback(dispatcher.bot, update, **optional_args)
  File "/Users/logan/PycharmProjects/MonopolyTelegramBot/telegram_interaction.py", line 471, in assets_handler
    send_info(bot, chat_id, game, user_id)
  File "/Users/logan/PycharmProjects/MonopolyTelegramBot/telegram_interaction.py", line 44, in send_info
    props = player.get_properties_str()
  File "/Users/logan/PycharmProjects/MonopolyTelegramBot/monopoly.py", line 83, in get_properties_str
    text += "(" + str(count) + ") " + p.get_name() + " : " + p.get_color() + "\n"
AttributeError: 'OtherProperty' object has no attribute 'get_color'
2019-06-15 13:41:29,028 - telegram.ext.dispatcher - ERROR - An uncaught error was raised while processing the update
Traceback (most recent call last):
  File "/usr/local/lib/python3.7/site-packages/telegram/ext/dispatcher.py", line 279, in process_update
    handler.handle_update(update, self)
  File "/usr/local/lib/python3.7/site-packages/telegram/ext/commandhandler.py", line 173, in handle_update
    return self.callback(dispatcher.bot, update, **optional_args)
  File "/Users/logan/PycharmProjects/MonopolyTelegramBot/telegram_interaction.py", line 471, in assets_handler
    send_info(bot, chat_id, game, user_id)
  File "/Users/logan/PycharmProjects/MonopolyTelegramBot/telegram_interaction.py", line 44, in send_info
    props = player.get_properties_str()
  File "/Users/logan/PycharmProjects/MonopolyTelegramBot/monopoly.py", line 83, in get_properties_str
    if p is Property:
AttributeError: 'OtherProperty' object has no attribute 'get_color'
2019-06-15 13:43:49,309 - telegram.ext.dispatcher - ERROR - An uncaught error was raised while processing the update
Traceback (most recent call last):
  File "/usr/local/lib/python3.7/site-packages/telegram/ext/dispatcher.py", line 279, in process_update
    handler.handle_update(update, self)
  File "/usr/local/lib/python3.7/site-packages/telegram/ext/commandhandler.py", line 173, in handle_update
    return self.callback(dispatcher.bot, update, **optional_args)
  File "/Users/logan/PycharmProjects/MonopolyTelegramBot/telegram_interaction.py", line 355, in bail_handler
    game.pay_bail(user_id)
  File "/Users/logan/PycharmProjects/MonopolyTelegramBot/monopoly.py", line 304, in pay_bail
    self.send_message("You are not currently in jail!")
  File "/Users/logan/PycharmProjects/MonopolyTelegramBot/monopoly.py", line 96, in get_total_assets
    def get_total_assets(self):
  File "/Users/logan/PycharmProjects/MonopolyTelegramBot/monopoly.py", line 96, in <listcomp>
    def get_total_assets(self):
AttributeError: 'OtherProperty' object has no attribute 'house_cost'
2019-06-15 13:47:52,155 - telegram.ext.dispatcher - ERROR - An uncaught error was raised while processing the update
Traceback (most recent call last):
  File "/usr/local/lib/python3.7/site-packages/telegram/ext/dispatcher.py", line 279, in process_update
    handler.handle_update(update, self)
  File "/usr/local/lib/python3.7/site-packages/telegram/ext/commandhandler.py", line 173, in handle_update
    return self.callback(dispatcher.bot, update, **optional_args)
  File "/Users/logan/PycharmProjects/MonopolyTelegramBot/telegram_interaction.py", line 241, in roll_handler
    game.roll_dice(user_id)
  File "/Users/logan/PycharmProjects/MonopolyTelegramBot/monopoly.py", line 1055, in roll_dice
    else:
  File "/Users/logan/PycharmProjects/MonopolyTelegramBot/monopoly.py", line 928, in enact_roll_result
    return
  File "/Users/logan/PycharmProjects/MonopolyTelegramBot/monopoly.py", line 857, in cc_result
    elif card == 1:
AttributeError: 'Player' object has no attribute 'add_out_of_free_card'
2019-06-15 13:57:58,455 - telegram.ext.dispatcher - ERROR - An uncaught error was raised while processing the update
Traceback (most recent call last):
  File "/usr/local/lib/python3.7/site-packages/telegram/ext/dispatcher.py", line 279, in process_update
    handler.handle_update(update, self)
  File "/usr/local/lib/python3.7/site-packages/telegram/ext/commandhandler.py", line 173, in handle_update
    return self.callback(dispatcher.bot, update, **optional_args)
  File "/Users/logan/PycharmProjects/MonopolyTelegramBot/telegram_interaction.py", line 355, in bail_handler
    game.pay_bail(user_id)
  File "/Users/logan/PycharmProjects/MonopolyTelegramBot/monopoly.py", line 304, in pay_bail
    if not self.check_player_existence_and_turn(player):
  File "/Users/logan/PycharmProjects/MonopolyTelegramBot/monopoly.py", line 96, in get_total_assets
    def get_total_assets(self):
  File "/Users/logan/PycharmProjects/MonopolyTelegramBot/monopoly.py", line 96, in <listcomp>
    def get_total_assets(self):
AttributeError: 'OtherProperty' object has no attribute 'house_cost'
2019-06-15 14:00:05,071 - telegram.ext.updater - INFO - Received signal 2 (SIGINT), stopping...
2019-06-15 16:17:36,013 - telegram.ext.updater - INFO - Received signal 2 (SIGINT), stopping...
2019-06-15 16:17:36,043 - telegram.ext.updater - INFO - Received signal 2 (SIGINT), stopping...
2019-06-15 16:22:46,719 - telegram.vendor.ptb_urllib3.urllib3.connectionpool - WARNING - Retrying (Retry(total=2, connect=None, read=None, redirect=None)) after connection broken by 'ConnectTimeoutError(<telegram.vendor.ptb_urllib3.urllib3.connection.VerifiedHTTPSConnection object at 0x109c081d0>, 'Connection to api.telegram.org timed out. (connect timeout=5.0)')': /bot854076226:AAGBGAeMq3le6mU2FpKcONa2b88D6A2-SzU/getUpdates
2019-06-15 16:22:51,726 - telegram.vendor.ptb_urllib3.urllib3.connectionpool - WARNING - Retrying (Retry(total=1, connect=None, read=None, redirect=None)) after connection broken by 'ConnectTimeoutError(<telegram.vendor.ptb_urllib3.urllib3.connection.VerifiedHTTPSConnection object at 0x109c08668>, 'Connection to api.telegram.org timed out. (connect timeout=5.0)')': /bot854076226:AAGBGAeMq3le6mU2FpKcONa2b88D6A2-SzU/getUpdates
2019-06-15 16:22:56,729 - telegram.vendor.ptb_urllib3.urllib3.connectionpool - WARNING - Retrying (Retry(total=0, connect=None, read=None, redirect=None)) after connection broken by 'ConnectTimeoutError(<telegram.vendor.ptb_urllib3.urllib3.connection.VerifiedHTTPSConnection object at 0x109c08710>, 'Connection to api.telegram.org timed out. (connect timeout=5.0)')': /bot854076226:AAGBGAeMq3le6mU2FpKcONa2b88D6A2-SzU/getUpdates
2019-06-15 16:24:11,929 - telegram.vendor.ptb_urllib3.urllib3.connectionpool - WARNING - Retrying (Retry(total=2, connect=None, read=None, redirect=None)) after connection broken by 'ConnectTimeoutError(<telegram.vendor.ptb_urllib3.urllib3.connectionpool.HTTPSConnectionPool object at 0x109bb6ef0>, 'Connect timed out. (connect timeout=5.0)')': /bot854076226:AAGBGAeMq3le6mU2FpKcONa2b88D6A2-SzU/getUpdates
2019-06-15 16:24:16,933 - telegram.vendor.ptb_urllib3.urllib3.connectionpool - WARNING - Retrying (Retry(total=1, connect=None, read=None, redirect=None)) after connection broken by 'ConnectTimeoutError(<telegram.vendor.ptb_urllib3.urllib3.connection.VerifiedHTTPSConnection object at 0x109c08780>, 'Connection to api.telegram.org timed out. (connect timeout=5.0)')': /bot854076226:AAGBGAeMq3le6mU2FpKcONa2b88D6A2-SzU/getUpdates
2019-06-15 16:24:25,411 - telegram.ext.dispatcher - WARNING - A TelegramError was raised while processing the Update
2019-06-15 16:24:25,413 - __main__ - WARNING - Telegram Error! urllib3 HTTPError ('Connection aborted.', ConnectionResetError(54, 'Connection reset by peer')) caused by this update: {'update_id': 662955633, 'message': {'message_id': 1422, 'date': 1560641064, 'chat': {'id': -282831889, 'type': 'group', 'title': 'Monopoly', 'all_members_are_administrators': True}, 'text': '/join', 'entities': [{'type': 'bot_command', 'offset': 0, 'length': 5}], 'caption_entities': [], 'photo': [], 'new_chat_members': [], 'new_chat_photo': [], 'delete_chat_photo': False, 'group_chat_created': False, 'supergroup_chat_created': False, 'channel_chat_created': False, 'from': {'id': 568017853, 'first_name': 'Aru', 'is_bot': False, 'last_name': 'M', 'username': 'a18071514', 'language_code': 'en'}}, '_effective_user': {'id': 568017853, 'first_name': 'Aru', 'is_bot': False, 'last_name': 'M', 'username': 'a18071514', 'language_code': 'en'}, '_effective_chat': {'id': -282831889, 'type': 'group', 'title': 'Monopoly', 'all_members_are_administrators': True}}
2019-06-15 16:25:31,639 - telegram.ext.dispatcher - ERROR - An uncaught error was raised while processing the update
Traceback (most recent call last):
  File "/usr/local/lib/python3.7/site-packages/telegram/ext/dispatcher.py", line 279, in process_update
    handler.handle_update(update, self)
  File "/usr/local/lib/python3.7/site-packages/telegram/ext/commandhandler.py", line 173, in handle_update
    return self.callback(dispatcher.bot, update, **optional_args)
  File "/Users/logan/PycharmProjects/MonopolyTelegramBot/telegram_interaction.py", line 458, in setup_trade_handler
    game.setup_trade(user_id, int(" ".join(args)))
  File "/Users/logan/PycharmProjects/MonopolyTelegramBot/monopoly.py", line 486, in setup_trade
    player_1 = self.get_player_by_local_id(id_1)
  File "/Users/logan/PycharmProjects/MonopolyTelegramBot/monopoly.py", line 309, in get_player_by_local_id
    if p.get_id() == id:
AttributeError: 'int' object has no attribute 'get_id'
2019-06-15 16:26:06,838 - telegram.ext.updater - INFO - Received signal 2 (SIGINT), stopping...
2019-06-15 16:26:49,337 - telegram.vendor.ptb_urllib3.urllib3.connectionpool - WARNING - Retrying (Retry(total=2, connect=None, read=None, redirect=None)) after connection broken by 'ConnectTimeoutError(<telegram.vendor.ptb_urllib3.urllib3.connection.VerifiedHTTPSConnection object at 0x10c06b940>, 'Connection to api.telegram.org timed out. (connect timeout=5.0)')': /bot854076226:AAGBGAeMq3le6mU2FpKcONa2b88D6A2-SzU/getUpdates
2019-06-15 16:28:35,552 - telegram.ext.updater - INFO - Received signal 2 (SIGINT), stopping...
2019-06-15 16:29:48,312 - telegram.ext.updater - INFO - Received signal 2 (SIGINT), stopping...
2019-06-15 16:31:21,917 - telegram.ext.updater - INFO - Received signal 2 (SIGINT), stopping...
2019-06-15 16:35:15,060 - telegram.ext.dispatcher - WARNING - A TelegramError was raised while processing the Update
2019-06-15 16:35:15,060 - __main__ - WARNING - Telegram Error! urllib3 HTTPError ('Connection aborted.', ConnectionResetError(54, 'Connection reset by peer')) caused by this update: {'update_id': 662955664, 'message': {'message_id': 1520, 'date': 1560641714, 'chat': {'id': -282831889, 'type': 'group', 'title': 'Monopoly', 'all_members_are_administrators': True}, 'text': '/addtrade -1 0 0', 'entities': [{'type': 'bot_command', 'offset': 0, 'length': 9}], 'caption_entities': [], 'photo': [], 'new_chat_members': [], 'new_chat_photo': [], 'delete_chat_photo': False, 'group_chat_created': False, 'supergroup_chat_created': False, 'channel_chat_created': False, 'from': {'id': 539621524, 'first_name': 'Logan', 'is_bot': False, 'last_name': 'Apple', 'language_code': 'en'}}, '_effective_user': {'id': 539621524, 'first_name': 'Logan', 'is_bot': False, 'last_name': 'Apple', 'language_code': 'en'}, '_effective_chat': {'id': -282831889, 'type': 'group', 'title': 'Monopoly', 'all_members_are_administrators': True}}
2019-06-15 16:37:35,925 - telegram.ext.dispatcher - WARNING - A TelegramError was raised while processing the Update
2019-06-15 16:37:35,925 - __main__ - WARNING - Telegram Error! urllib3 HTTPError ('Connection aborted.', ConnectionResetError(54, 'Connection reset by peer')) caused by this update: {'update_id': 662955668, 'message': {'message_id': 1531, 'date': 1560641855, 'chat': {'id': -282831889, 'type': 'group', 'title': 'Monopoly', 'all_members_are_administrators': True}, 'text': '/assets', 'entities': [{'type': 'bot_command', 'offset': 0, 'length': 7}], 'caption_entities': [], 'photo': [], 'new_chat_members': [], 'new_chat_photo': [], 'delete_chat_photo': False, 'group_chat_created': False, 'supergroup_chat_created': False, 'channel_chat_created': False, 'from': {'id': 539621524, 'first_name': 'Logan', 'is_bot': False, 'last_name': 'Apple', 'language_code': 'en'}}, '_effective_user': {'id': 539621524, 'first_name': 'Logan', 'is_bot': False, 'last_name': 'Apple', 'language_code': 'en'}, '_effective_chat': {'id': -282831889, 'type': 'group', 'title': 'Monopoly', 'all_members_are_administrators': True}}
2019-06-15 16:37:51,994 - telegram.vendor.ptb_urllib3.urllib3.connectionpool - WARNING - Retrying (Retry(total=2, connect=None, read=None, redirect=None)) after connection broken by 'ConnectTimeoutError(<telegram.vendor.ptb_urllib3.urllib3.connectionpool.HTTPSConnectionPool object at 0x10f142f28>, 'Connect timed out. (connect timeout=5.0)')': /bot854076226:AAGBGAeMq3le6mU2FpKcONa2b88D6A2-SzU/getUpdates
2019-06-15 16:37:55,162 - telegram.ext.updater - INFO - Received signal 2 (SIGINT), stopping...
2019-06-15 16:40:42,150 - telegram.ext.dispatcher - ERROR - An uncaught error was raised while processing the update
Traceback (most recent call last):
  File "/usr/local/lib/python3.7/site-packages/telegram/ext/dispatcher.py", line 279, in process_update
    handler.handle_update(update, self)
  File "/usr/local/lib/python3.7/site-packages/telegram/ext/commandhandler.py", line 173, in handle_update
    return self.callback(dispatcher.bot, update, **optional_args)
  File "/Users/logan/PycharmProjects/MonopolyTelegramBot/telegram_interaction.py", line 396, in add_to_trade_handler
    game.add_to_trade(user_id, int(args[0]), int(args[1]), int(args[2]))
  File "/Users/logan/PycharmProjects/MonopolyTelegramBot/monopoly.py", line 559, in add_to_trade
    if prop >= 0: self.pending_trade[4] += property
TypeError: 'Property' object is not iterable
2019-06-15 16:40:52,156 - telegram.vendor.ptb_urllib3.urllib3.connectionpool - WARNING - Retrying (Retry(total=2, connect=None, read=None, redirect=None)) after connection broken by 'ConnectTimeoutError(<telegram.vendor.ptb_urllib3.urllib3.connection.VerifiedHTTPSConnection object at 0x106dbac18>, 'Connection to api.telegram.org timed out. (connect timeout=5.0)')': /bot854076226:AAGBGAeMq3le6mU2FpKcONa2b88D6A2-SzU/getUpdates
2019-06-15 16:41:22,820 - telegram.ext.updater - INFO - Received signal 2 (SIGINT), stopping...
2019-06-15 16:44:49,500 - telegram.ext.dispatcher - WARNING - A TelegramError was raised while processing the Update
2019-06-15 16:44:49,500 - __main__ - WARNING - Telegram Error! urllib3 HTTPError ('Connection aborted.', ConnectionResetError(54, 'Connection reset by peer')) caused by this update: {'update_id': 662955699, 'message': {'message_id': 1620, 'date': 1560642289, 'chat': {'id': -282831889, 'type': 'group', 'title': 'Monopoly', 'all_members_are_administrators': True}, 'text': '/assets', 'entities': [{'type': 'bot_command', 'offset': 0, 'length': 7}], 'caption_entities': [], 'photo': [], 'new_chat_members': [], 'new_chat_photo': [], 'delete_chat_photo': False, 'group_chat_created': False, 'supergroup_chat_created': False, 'channel_chat_created': False, 'from': {'id': 539621524, 'first_name': 'Logan', 'is_bot': False, 'last_name': 'Apple', 'language_code': 'en'}}, '_effective_user': {'id': 539621524, 'first_name': 'Logan', 'is_bot': False, 'last_name': 'Apple', 'language_code': 'en'}, '_effective_chat': {'id': -282831889, 'type': 'group', 'title': 'Monopoly', 'all_members_are_administrators': True}}
2019-06-15 16:47:14,733 - telegram.ext.dispatcher - WARNING - A TelegramError was raised while processing the Update
2019-06-15 16:47:14,734 - __main__ - WARNING - Telegram Error! urllib3 HTTPError ('Connection aborted.', ConnectionResetError(54, 'Connection reset by peer')) caused by this update: {'update_id': 662955702, 'message': {'message_id': 1625, 'date': 1560642434, 'chat': {'id': -282831889, 'type': 'group', 'title': 'Monopoly', 'all_members_are_administrators': True}, 'text': '/assets', 'entities': [{'type': 'bot_command', 'offset': 0, 'length': 7}], 'caption_entities': [], 'photo': [], 'new_chat_members': [], 'new_chat_photo': [], 'delete_chat_photo': False, 'group_chat_created': False, 'supergroup_chat_created': False, 'channel_chat_created': False, 'from': {'id': 568017853, 'first_name': 'Aru', 'is_bot': False, 'last_name': 'M', 'username': 'a18071514', 'language_code': 'en'}}, '_effective_user': {'id': 568017853, 'first_name': 'Aru', 'is_bot': False, 'last_name': 'M', 'username': 'a18071514', 'language_code': 'en'}, '_effective_chat': {'id': -282831889, 'type': 'group', 'title': 'Monopoly', 'all_members_are_administrators': True}}
2019-06-15 16:48:42,384 - telegram.ext.dispatcher - WARNING - A TelegramError was raised while processing the Update
2019-06-15 16:48:42,386 - __main__ - WARNING - Telegram Error! urllib3 HTTPError ('Connection aborted.', ConnectionResetError(54, 'Connection reset by peer')) caused by this update: {'update_id': 662955703, 'message': {'message_id': 1626, 'date': 1560642521, 'chat': {'id': -282831889, 'type': 'group', 'title': 'Monopoly', 'all_members_are_administrators': True}, 'text': '/endturn', 'entities': [{'type': 'bot_command', 'offset': 0, 'length': 8}], 'caption_entities': [], 'photo': [], 'new_chat_members': [], 'new_chat_photo': [], 'delete_chat_photo': False, 'group_chat_created': False, 'supergroup_chat_created': False, 'channel_chat_created': False, 'from': {'id': 539621524, 'first_name': 'Logan', 'is_bot': False, 'last_name': 'Apple', 'language_code': 'en'}}, '_effective_user': {'id': 539621524, 'first_name': 'Logan', 'is_bot': False, 'last_name': 'Apple', 'language_code': 'en'}, '_effective_chat': {'id': -282831889, 'type': 'group', 'title': 'Monopoly', 'all_members_are_administrators': True}}
2019-06-15 16:48:52,145 - telegram.ext.updater - INFO - Received signal 2 (SIGINT), stopping...
2019-06-15 16:53:59,328 - telegram.vendor.ptb_urllib3.urllib3.connectionpool - WARNING - Retrying (Retry(total=2, connect=None, read=None, redirect=None)) after connection broken by 'ConnectTimeoutError(<telegram.vendor.ptb_urllib3.urllib3.connection.VerifiedHTTPSConnection object at 0x101e25e80>, 'Connection to api.telegram.org timed out. (connect timeout=5.0)')': /bot854076226:AAGBGAeMq3le6mU2FpKcONa2b88D6A2-SzU/getUpdates
2019-06-15 16:54:35,310 - telegram.ext.dispatcher - WARNING - A TelegramError was raised while processing the Update
2019-06-15 16:54:35,310 - __main__ - WARNING - Telegram Error! urllib3 HTTPError ('Connection aborted.', ConnectionResetError(54, 'Connection reset by peer')) caused by this update: {'update_id': 662955738, 'message': {'message_id': 1720, 'date': 1560642874, 'chat': {'id': -282831889, 'type': 'group', 'title': 'Monopoly', 'all_members_are_administrators': True}, 'text': '/endgame', 'entities': [{'type': 'bot_command', 'offset': 0, 'length': 8}], 'caption_entities': [], 'photo': [], 'new_chat_members': [], 'new_chat_photo': [], 'delete_chat_photo': False, 'group_chat_created': False, 'supergroup_chat_created': False, 'channel_chat_created': False, 'from': {'id': 539621524, 'first_name': 'Logan', 'is_bot': False, 'last_name': 'Apple', 'language_code': 'en'}}, '_effective_user': {'id': 539621524, 'first_name': 'Logan', 'is_bot': False, 'last_name': 'Apple', 'language_code': 'en'}, '_effective_chat': {'id': -282831889, 'type': 'group', 'title': 'Monopoly', 'all_members_are_administrators': True}}
2019-06-15 16:54:44,925 - telegram.ext.updater - INFO - Received signal 2 (SIGINT), stopping...
2019-06-15 16:58:03,949 - telegram.ext.dispatcher - WARNING - A TelegramError was raised while processing the Update
2019-06-15 16:58:03,949 - __main__ - WARNING - Telegram Error! urllib3 HTTPError ('Connection aborted.', ConnectionResetError(54, 'Connection reset by peer')) caused by this update: {'update_id': 662955747, 'message': {'message_id': 1748, 'date': 1560643082, 'chat': {'id': -282831889, 'type': 'group', 'title': 'Monopoly', 'all_members_are_administrators': True}, 'text': '/endturn', 'entities': [{'type': 'bot_command', 'offset': 0, 'length': 8}], 'caption_entities': [], 'photo': [], 'new_chat_members': [], 'new_chat_photo': [], 'delete_chat_photo': False, 'group_chat_created': False, 'supergroup_chat_created': False, 'channel_chat_created': False, 'from': {'id': 568017853, 'first_name': 'Aru', 'is_bot': False, 'last_name': 'M', 'username': 'a18071514', 'language_code': 'en'}}, '_effective_user': {'id': 568017853, 'first_name': 'Aru', 'is_bot': False, 'last_name': 'M', 'username': 'a18071514', 'language_code': 'en'}, '_effective_chat': {'id': -282831889, 'type': 'group', 'title': 'Monopoly', 'all_members_are_administrators': True}}
2019-06-15 16:58:47,354 - telegram.ext.dispatcher - WARNING - A TelegramError was raised while processing the Update
2019-06-15 16:58:47,356 - __main__ - WARNING - Telegram Error! Timed out caused by this update: {'update_id': 662955752, 'message': {'message_id': 1760, 'date': 1560643122, 'chat': {'id': -282831889, 'type': 'group', 'title': 'Monopoly', 'all_members_are_administrators': True}, 'text': '/bp', 'entities': [{'type': 'bot_command', 'offset': 0, 'length': 3}], 'caption_entities': [], 'photo': [], 'new_chat_members': [], 'new_chat_photo': [], 'delete_chat_photo': False, 'group_chat_created': False, 'supergroup_chat_created': False, 'channel_chat_created': False, 'from': {'id': 568017853, 'first_name': 'Aru', 'is_bot': False, 'last_name': 'M', 'username': 'a18071514', 'language_code': 'en'}}, '_effective_user': {'id': 568017853, 'first_name': 'Aru', 'is_bot': False, 'last_name': 'M', 'username': 'a18071514', 'language_code': 'en'}, '_effective_chat': {'id': -282831889, 'type': 'group', 'title': 'Monopoly', 'all_members_are_administrators': True}}
2019-06-15 16:59:33,210 - telegram.ext.dispatcher - WARNING - A TelegramError was raised while processing the Update
2019-06-15 16:59:33,210 - __main__ - WARNING - Telegram Error! urllib3 HTTPError ('Connection aborted.', ConnectionResetError(54, 'Connection reset by peer')) caused by this update: {'update_id': 662955760, 'message': {'message_id': 1781, 'date': 1560643172, 'chat': {'id': -282831889, 'type': 'group', 'title': 'Monopoly', 'all_members_are_administrators': True}, 'text': '/assets', 'entities': [{'type': 'bot_command', 'offset': 0, 'length': 7}], 'caption_entities': [], 'photo': [], 'new_chat_members': [], 'new_chat_photo': [], 'delete_chat_photo': False, 'group_chat_created': False, 'supergroup_chat_created': False, 'channel_chat_created': False, 'from': {'id': 539621524, 'first_name': 'Logan', 'is_bot': False, 'last_name': 'Apple', 'language_code': 'en'}}, '_effective_user': {'id': 539621524, 'first_name': 'Logan', 'is_bot': False, 'last_name': 'Apple', 'language_code': 'en'}, '_effective_chat': {'id': -282831889, 'type': 'group', 'title': 'Monopoly', 'all_members_are_administrators': True}}
2019-06-15 17:01:10,940 - telegram.ext.dispatcher - WARNING - A TelegramError was raised while processing the Update
2019-06-15 17:01:10,940 - __main__ - WARNING - Telegram Error! urllib3 HTTPError ('Connection aborted.', ConnectionResetError(54, 'Connection reset by peer')) caused by this update: {'update_id': 662955765, 'message': {'message_id': 1790, 'date': 1560643270, 'chat': {'id': -282831889, 'type': 'group', 'title': 'Monopoly', 'all_members_are_administrators': True}, 'text': '/addtrade 0 0 0', 'entities': [{'type': 'bot_command', 'offset': 0, 'length': 9}], 'caption_entities': [], 'photo': [], 'new_chat_members': [], 'new_chat_photo': [], 'delete_chat_photo': False, 'group_chat_created': False, 'supergroup_chat_created': False, 'channel_chat_created': False, 'from': {'id': 568017853, 'first_name': 'Aru', 'is_bot': False, 'last_name': 'M', 'username': 'a18071514', 'language_code': 'en'}}, '_effective_user': {'id': 568017853, 'first_name': 'Aru', 'is_bot': False, 'last_name': 'M', 'username': 'a18071514', 'language_code': 'en'}, '_effective_chat': {'id': -282831889, 'type': 'group', 'title': 'Monopoly', 'all_members_are_administrators': True}}
2019-06-15 17:01:48,529 - telegram.ext.dispatcher - WARNING - A TelegramError was raised while processing the Update
2019-06-15 17:01:48,529 - __main__ - WARNING - Telegram Error! urllib3 HTTPError ('Connection aborted.', ConnectionResetError(54, 'Connection reset by peer')) caused by this update: {'update_id': 662955769, 'message': {'message_id': 1802, 'date': 1560643307, 'chat': {'id': -282831889, 'type': 'group', 'title': 'Monopoly', 'all_members_are_administrators': True}, 'text': '/assets', 'entities': [{'type': 'bot_command', 'offset': 0, 'length': 7}], 'caption_entities': [], 'photo': [], 'new_chat_members': [], 'new_chat_photo': [], 'delete_chat_photo': False, 'group_chat_created': False, 'supergroup_chat_created': False, 'channel_chat_created': False, 'from': {'id': 539621524, 'first_name': 'Logan', 'is_bot': False, 'last_name': 'Apple', 'language_code': 'en'}}, '_effective_user': {'id': 539621524, 'first_name': 'Logan', 'is_bot': False, 'last_name': 'Apple', 'language_code': 'en'}, '_effective_chat': {'id': -282831889, 'type': 'group', 'title': 'Monopoly', 'all_members_are_administrators': True}}
2019-06-15 17:05:26,057 - telegram.ext.dispatcher - WARNING - A TelegramError was raised while processing the Update
2019-06-15 17:05:26,059 - __main__ - WARNING - Telegram Error! urllib3 HTTPError ('Connection aborted.', ConnectionResetError(54, 'Connection reset by peer')) caused by this update: {'update_id': 662955794, 'message': {'message_id': 1870, 'date': 1560643525, 'chat': {'id': -282831889, 'type': 'group', 'title': 'Monopoly', 'all_members_are_administrators': True}, 'text': '/assets', 'entities': [{'type': 'bot_command', 'offset': 0, 'length': 7}], 'caption_entities': [], 'photo': [], 'new_chat_members': [], 'new_chat_photo': [], 'delete_chat_photo': False, 'group_chat_created': False, 'supergroup_chat_created': False, 'channel_chat_created': False, 'from': {'id': 539621524, 'first_name': 'Logan', 'is_bot': False, 'last_name': 'Apple', 'language_code': 'en'}}, '_effective_user': {'id': 539621524, 'first_name': 'Logan', 'is_bot': False, 'last_name': 'Apple', 'language_code': 'en'}, '_effective_chat': {'id': -282831889, 'type': 'group', 'title': 'Monopoly', 'all_members_are_administrators': True}}
2019-06-15 17:06:26,293 - telegram.ext.updater - INFO - Received signal 2 (SIGINT), stopping...
2019-06-15 17:06:51,791 - telegram.vendor.ptb_urllib3.urllib3.connectionpool - WARNING - Retrying (Retry(total=2, connect=None, read=None, redirect=None)) after connection broken by 'ConnectTimeoutError(<telegram.vendor.ptb_urllib3.urllib3.connection.VerifiedHTTPSConnection object at 0x105996160>, 'Connection to api.telegram.org timed out. (connect timeout=5.0)')': /bot854076226:AAGBGAeMq3le6mU2FpKcONa2b88D6A2-SzU/getUpdates
2019-06-15 17:26:16,700 - telegram.vendor.ptb_urllib3.urllib3.connectionpool - WARNING - Retrying (Retry(total=2, connect=None, read=None, redirect=None)) after connection broken by 'ConnectTimeoutError(<telegram.vendor.ptb_urllib3.urllib3.connection.VerifiedHTTPSConnection object at 0x1059a8a58>, 'Connection to api.telegram.org timed out. (connect timeout=5.0)')': /bot854076226:AAGBGAeMq3le6mU2FpKcONa2b88D6A2-SzU/getUpdates
2019-06-15 17:26:16,701 - telegram.vendor.ptb_urllib3.urllib3.connectionpool - WARNING - Retrying (Retry(total=1, connect=None, read=None, redirect=None)) after connection broken by 'NewConnectionError('<telegram.vendor.ptb_urllib3.urllib3.connection.VerifiedHTTPSConnection object at 0x105996e48>: Failed to establish a new connection: [Errno 8] nodename nor servname provided, or not known')': /bot854076226:AAGBGAeMq3le6mU2FpKcONa2b88D6A2-SzU/getUpdates
2019-06-15 17:26:16,702 - telegram.vendor.ptb_urllib3.urllib3.connectionpool - WARNING - Retrying (Retry(total=0, connect=None, read=None, redirect=None)) after connection broken by 'NewConnectionError('<telegram.vendor.ptb_urllib3.urllib3.connection.VerifiedHTTPSConnection object at 0x105996b38>: Failed to establish a new connection: [Errno 8] nodename nor servname provided, or not known')': /bot854076226:AAGBGAeMq3le6mU2FpKcONa2b88D6A2-SzU/getUpdates
2019-06-15 17:26:16,703 - telegram.ext.updater - ERROR - Error while getting Updates: urllib3 HTTPError HTTPSConnectionPool(host='api.telegram.org', port=443): Max retries exceeded with url: /bot854076226:AAGBGAeMq3le6mU2FpKcONa2b88D6A2-SzU/getUpdates (Caused by NewConnectionError('<telegram.vendor.ptb_urllib3.urllib3.connection.VerifiedHTTPSConnection object at 0x105996d68>: Failed to establish a new connection: [Errno 8] nodename nor servname provided, or not known'))
2019-06-15 17:26:16,703 - __main__ - WARNING - Telegram Error! urllib3 HTTPError HTTPSConnectionPool(host='api.telegram.org', port=443): Max retries exceeded with url: /bot854076226:AAGBGAeMq3le6mU2FpKcONa2b88D6A2-SzU/getUpdates (Caused by NewConnectionError('<telegram.vendor.ptb_urllib3.urllib3.connection.VerifiedHTTPSConnection object at 0x105996d68>: Failed to establish a new connection: [Errno 8] nodename nor servname provided, or not known')) caused by this update: None
2019-06-15 17:26:17,708 - telegram.vendor.ptb_urllib3.urllib3.connectionpool - WARNING - Retrying (Retry(total=2, connect=None, read=None, redirect=None)) after connection broken by 'NewConnectionError('<telegram.vendor.ptb_urllib3.urllib3.connection.VerifiedHTTPSConnection object at 0x1059967b8>: Failed to establish a new connection: [Errno 8] nodename nor servname provided, or not known')': /bot854076226:AAGBGAeMq3le6mU2FpKcONa2b88D6A2-SzU/getUpdates
2019-06-15 17:26:17,709 - telegram.vendor.ptb_urllib3.urllib3.connectionpool - WARNING - Retrying (Retry(total=1, connect=None, read=None, redirect=None)) after connection broken by 'NewConnectionError('<telegram.vendor.ptb_urllib3.urllib3.connection.VerifiedHTTPSConnection object at 0x105996a20>: Failed to establish a new connection: [Errno 8] nodename nor servname provided, or not known')': /bot854076226:AAGBGAeMq3le6mU2FpKcONa2b88D6A2-SzU/getUpdates
2019-06-15 17:26:17,711 - telegram.vendor.ptb_urllib3.urllib3.connectionpool - WARNING - Retrying (Retry(total=0, connect=None, read=None, redirect=None)) after connection broken by 'NewConnectionError('<telegram.vendor.ptb_urllib3.urllib3.connection.VerifiedHTTPSConnection object at 0x105996b70>: Failed to establish a new connection: [Errno 8] nodename nor servname provided, or not known')': /bot854076226:AAGBGAeMq3le6mU2FpKcONa2b88D6A2-SzU/getUpdates
2019-06-15 17:26:17,713 - telegram.ext.updater - ERROR - Error while getting Updates: urllib3 HTTPError HTTPSConnectionPool(host='api.telegram.org', port=443): Max retries exceeded with url: /bot854076226:AAGBGAeMq3le6mU2FpKcONa2b88D6A2-SzU/getUpdates (Caused by NewConnectionError('<telegram.vendor.ptb_urllib3.urllib3.connection.VerifiedHTTPSConnection object at 0x1059960f0>: Failed to establish a new connection: [Errno 8] nodename nor servname provided, or not known'))
2019-06-15 17:26:17,713 - __main__ - WARNING - Telegram Error! urllib3 HTTPError HTTPSConnectionPool(host='api.telegram.org', port=443): Max retries exceeded with url: /bot854076226:AAGBGAeMq3le6mU2FpKcONa2b88D6A2-SzU/getUpdates (Caused by NewConnectionError('<telegram.vendor.ptb_urllib3.urllib3.connection.VerifiedHTTPSConnection object at 0x1059960f0>: Failed to establish a new connection: [Errno 8] nodename nor servname provided, or not known')) caused by this update: None
2019-06-15 17:26:19,219 - telegram.vendor.ptb_urllib3.urllib3.connectionpool - WARNING - Retrying (Retry(total=2, connect=None, read=None, redirect=None)) after connection broken by 'NewConnectionError('<telegram.vendor.ptb_urllib3.urllib3.connection.VerifiedHTTPSConnection object at 0x10595d1d0>: Failed to establish a new connection: [Errno 8] nodename nor servname provided, or not known')': /bot854076226:AAGBGAeMq3le6mU2FpKcONa2b88D6A2-SzU/getUpdates
2019-06-15 17:26:19,220 - telegram.vendor.ptb_urllib3.urllib3.connectionpool - WARNING - Retrying (Retry(total=1, connect=None, read=None, redirect=None)) after connection broken by 'NewConnectionError('<telegram.vendor.ptb_urllib3.urllib3.connection.VerifiedHTTPSConnection object at 0x105952eb8>: Failed to establish a new connection: [Errno 8] nodename nor servname provided, or not known')': /bot854076226:AAGBGAeMq3le6mU2FpKcONa2b88D6A2-SzU/getUpdates
2019-06-15 17:26:19,222 - telegram.vendor.ptb_urllib3.urllib3.connectionpool - WARNING - Retrying (Retry(total=0, connect=None, read=None, redirect=None)) after connection broken by 'NewConnectionError('<telegram.vendor.ptb_urllib3.urllib3.connection.VerifiedHTTPSConnection object at 0x105973eb8>: Failed to establish a new connection: [Errno 8] nodename nor servname provided, or not known')': /bot854076226:AAGBGAeMq3le6mU2FpKcONa2b88D6A2-SzU/getUpdates
2019-06-15 17:26:19,225 - telegram.ext.updater - ERROR - Error while getting Updates: urllib3 HTTPError HTTPSConnectionPool(host='api.telegram.org', port=443): Max retries exceeded with url: /bot854076226:AAGBGAeMq3le6mU2FpKcONa2b88D6A2-SzU/getUpdates (Caused by NewConnectionError('<telegram.vendor.ptb_urllib3.urllib3.connection.VerifiedHTTPSConnection object at 0x105973cf8>: Failed to establish a new connection: [Errno 8] nodename nor servname provided, or not known'))
2019-06-15 17:26:19,225 - __main__ - WARNING - Telegram Error! urllib3 HTTPError HTTPSConnectionPool(host='api.telegram.org', port=443): Max retries exceeded with url: /bot854076226:AAGBGAeMq3le6mU2FpKcONa2b88D6A2-SzU/getUpdates (Caused by NewConnectionError('<telegram.vendor.ptb_urllib3.urllib3.connection.VerifiedHTTPSConnection object at 0x105973cf8>: Failed to establish a new connection: [Errno 8] nodename nor servname provided, or not known')) caused by this update: None
2019-06-15 17:26:20,349 - telegram.ext.updater - INFO - Received signal 2 (SIGINT), stopping...
2019-07-11 21:12:08,398 - telegram.ext.dispatcher - ERROR - An uncaught error was raised while processing the update
Traceback (most recent call last):
  File "/usr/local/lib/python3.7/site-packages/telegram/ext/dispatcher.py", line 279, in process_update
    handler.handle_update(update, self)
  File "/usr/local/lib/python3.7/site-packages/telegram/ext/commandhandler.py", line 173, in handle_update
    return self.callback(dispatcher.bot, update, **optional_args)
  File "/Users/logan/PycharmProjects/MonopolyTelegramBot/telegram_interaction.py", line 333, in pay_handler
    game.pay(user_id, int(args[0]), int(args[1]))
ValueError: invalid literal for int() with base 10: 'bank'
2019-07-11 21:16:53,111 - telegram.ext.dispatcher - ERROR - An uncaught error was raised while processing the update
Traceback (most recent call last):
  File "/usr/local/lib/python3.7/site-packages/telegram/ext/dispatcher.py", line 279, in process_update
    handler.handle_update(update, self)
  File "/usr/local/lib/python3.7/site-packages/telegram/ext/commandhandler.py", line 173, in handle_update
    return self.callback(dispatcher.bot, update, **optional_args)
  File "/Users/logan/PycharmProjects/MonopolyTelegramBot/telegram_interaction.py", line 143, in listplayers_handler
    text += "(" + str(game.get_player(user_id).get_id()) + ") " + name + "\n"
AttributeError: 'Game' object has no attribute 'get_player'
2019-07-11 21:17:12,874 - telegram.ext.dispatcher - ERROR - An uncaught error was raised while processing the update
Traceback (most recent call last):
  File "/usr/local/lib/python3.7/site-packages/telegram/ext/dispatcher.py", line 279, in process_update
    handler.handle_update(update, self)
  File "/usr/local/lib/python3.7/site-packages/telegram/ext/commandhandler.py", line 173, in handle_update
    return self.callback(dispatcher.bot, update, **optional_args)
  File "/Users/logan/PycharmProjects/MonopolyTelegramBot/telegram_interaction.py", line 143, in listplayers_handler
    text += "(" + str(game.get_player(user_id).get_id()) + ") " + name + "\n"
AttributeError: 'Game' object has no attribute 'get_player'
2019-07-11 21:30:48,590 - telegram.ext.dispatcher - ERROR - An uncaught error was raised while processing the update
Traceback (most recent call last):
  File "/usr/local/lib/python3.7/site-packages/telegram/ext/dispatcher.py", line 279, in process_update
    handler.handle_update(update, self)
  File "/usr/local/lib/python3.7/site-packages/telegram/ext/commandhandler.py", line 173, in handle_update
    return self.callback(dispatcher.bot, update, **optional_args)
  File "/Users/logan/PycharmProjects/MonopolyTelegramBot/telegram_interaction.py", line 370, in mortgage_handler
    game.mortgage_property(user_id, int(" ".join(args)))
ValueError: invalid literal for int() with base 10: 'prop_id'
2019-07-11 21:33:58,475 - telegram.ext.dispatcher - ERROR - An uncaught error was raised while processing the update
Traceback (most recent call last):
  File "/usr/local/lib/python3.7/site-packages/telegram/ext/dispatcher.py", line 279, in process_update
    handler.handle_update(update, self)
  File "/usr/local/lib/python3.7/site-packages/telegram/ext/commandhandler.py", line 173, in handle_update
    return self.callback(dispatcher.bot, update, **optional_args)
  File "/Users/logan/PycharmProjects/MonopolyTelegramBot/telegram_interaction.py", line 370, in mortgage_handler
    game.mortgage_property(user_id, int(" ".join(args)))
  File "/Users/logan/PycharmProjects/MonopolyTelegramBot/monopoly.py", line 466, in mortgage_property
    if property.mortgaged():
TypeError: 'bool' object is not callable
2019-07-11 21:36:37,380 - telegram.ext.dispatcher - WARNING - A TelegramError was raised while processing the Update
2019-07-11 21:36:37,382 - __main__ - WARNING - Telegram Error! Timed out caused by this update: {'update_id': 662955963, 'message': {'message_id': 2315, 'date': 1562906186, 'chat': {'id': -282831889, 'type': 'group', 'title': 'Monopoly', 'all_members_are_administrators': True}, 'text': '/bankrupt 0', 'entities': [{'type': 'bot_command', 'offset': 0, 'length': 9}], 'caption_entities': [], 'photo': [], 'new_chat_members': [], 'new_chat_photo': [], 'delete_chat_photo': False, 'group_chat_created': False, 'supergroup_chat_created': False, 'channel_chat_created': False, 'from': {'id': 568017853, 'first_name': 'Aru', 'is_bot': False, 'last_name': 'M', 'username': 'a18071514', 'language_code': 'en'}}, '_effective_user': {'id': 568017853, 'first_name': 'Aru', 'is_bot': False, 'last_name': 'M', 'username': 'a18071514', 'language_code': 'en'}, '_effective_chat': {'id': -282831889, 'type': 'group', 'title': 'Monopoly', 'all_members_are_administrators': True}}
2019-07-11 21:37:49,545 - telegram.ext.updater - INFO - Received signal 2 (SIGINT), stopping...
2019-09-07 11:16:20,844 - telegram.ext.dispatcher - ERROR - An uncaught error was raised while processing the update
Traceback (most recent call last):
  File "/usr/local/lib/python3.7/site-packages/telegram/ext/dispatcher.py", line 279, in process_update
    handler.handle_update(update, self)
  File "/usr/local/lib/python3.7/site-packages/telegram/ext/commandhandler.py", line 173, in handle_update
    return self.callback(dispatcher.bot, update, **optional_args)
  File "/Users/logan/PycharmProjects/MonopolyTelegramBot/telegram_interaction.py", line 333, in pay_handler
    game.pay(user_id, int(args[0]), int(args[1]))
ValueError: invalid literal for int() with base 10: 'bank'
2019-09-07 11:16:41,751 - telegram.ext.dispatcher - ERROR - An uncaught error was raised while processing the update
Traceback (most recent call last):
  File "/usr/local/lib/python3.7/site-packages/telegram/ext/dispatcher.py", line 279, in process_update
    handler.handle_update(update, self)
  File "/usr/local/lib/python3.7/site-packages/telegram/ext/commandhandler.py", line 173, in handle_update
    return self.callback(dispatcher.bot, update, **optional_args)
  File "/Users/logan/PycharmProjects/MonopolyTelegramBot/telegram_interaction.py", line 333, in pay_handler
    game.pay(user_id, int(args[0]), int(args[1]))
ValueError: invalid literal for int() with base 10: 'bank'
2019-09-07 11:18:04,110 - telegram.ext.dispatcher - ERROR - An uncaught error was raised while processing the update
Traceback (most recent call last):
  File "/usr/local/lib/python3.7/site-packages/telegram/ext/dispatcher.py", line 279, in process_update
    handler.handle_update(update, self)
  File "/usr/local/lib/python3.7/site-packages/telegram/ext/commandhandler.py", line 173, in handle_update
    return self.callback(dispatcher.bot, update, **optional_args)
  File "/Users/logan/PycharmProjects/MonopolyTelegramBot/telegram_interaction.py", line 333, in pay_handler
    game.pay(user_id, int(args[0]), int(args[1]))
ValueError: invalid literal for int() with base 10: 'bank'
2019-09-07 11:20:48,223 - telegram.ext.updater - INFO - Received signal 2 (SIGINT), stopping...
2019-09-07 11:25:10,779 - telegram.ext.dispatcher - ERROR - An uncaught error was raised while processing the update
Traceback (most recent call last):
  File "/usr/local/lib/python3.7/site-packages/telegram/ext/dispatcher.py", line 279, in process_update
    handler.handle_update(update, self)
  File "/usr/local/lib/python3.7/site-packages/telegram/ext/commandhandler.py", line 173, in handle_update
    return self.callback(dispatcher.bot, update, **optional_args)
  File "/Users/logan/PycharmProjects/MonopolyTelegramBot/telegram_interaction.py", line 333, in pay_handler
    game.pay(user_id, int(args[0]), int(args[1]))
ValueError: invalid literal for int() with base 10: 'bank'
2019-09-07 11:25:55,194 - telegram.ext.dispatcher - ERROR - An uncaught error was raised while processing the update
Traceback (most recent call last):
  File "/usr/local/lib/python3.7/site-packages/telegram/ext/dispatcher.py", line 279, in process_update
    handler.handle_update(update, self)
  File "/usr/local/lib/python3.7/site-packages/telegram/ext/commandhandler.py", line 173, in handle_update
    return self.callback(dispatcher.bot, update, **optional_args)
  File "/Users/logan/PycharmProjects/MonopolyTelegramBot/telegram_interaction.py", line 333, in pay_handler
    game.pay(user_id, int(args[0]), int(args[1]))
ValueError: invalid literal for int() with base 10: 'bank'
2019-09-07 11:26:10,970 - telegram.ext.updater - INFO - Received signal 2 (SIGINT), stopping...
2019-09-07 11:28:04,473 - telegram.ext.dispatcher - ERROR - An uncaught error was raised while processing the update
Traceback (most recent call last):
  File "/usr/local/lib/python3.7/site-packages/telegram/ext/dispatcher.py", line 279, in process_update
    handler.handle_update(update, self)
  File "/usr/local/lib/python3.7/site-packages/telegram/ext/commandhandler.py", line 173, in handle_update
    return self.callback(dispatcher.bot, update, **optional_args)
  File "/Users/logan/PycharmProjects/MonopolyTelegramBot/telegram_interaction.py", line 315, in end_turn_handler
    game.end_turn(user_id)
  File "/Users/logan/PycharmProjects/MonopolyTelegramBot/monopoly.py", line 427, in end_turn
    self.players.get(self.turn).get_name())
AttributeError: 'NoneType' object has no attribute 'get_name'
2019-09-07 11:29:13,437 - telegram.ext.dispatcher - ERROR - An uncaught error was raised while processing the update
Traceback (most recent call last):
  File "/usr/local/lib/python3.7/site-packages/telegram/ext/dispatcher.py", line 279, in process_update
    handler.handle_update(update, self)
  File "/usr/local/lib/python3.7/site-packages/telegram/ext/commandhandler.py", line 173, in handle_update
    return self.callback(dispatcher.bot, update, **optional_args)
  File "/Users/logan/PycharmProjects/MonopolyTelegramBot/telegram_interaction.py", line 315, in end_turn_handler
    game.end_turn(user_id)
  File "/Users/logan/PycharmProjects/MonopolyTelegramBot/monopoly.py", line 427, in end_turn
    self.players.get(self.turn).get_name())
AttributeError: 'NoneType' object has no attribute 'get_name'
2019-09-07 11:29:19,825 - telegram.ext.dispatcher - ERROR - An uncaught error was raised while processing the update
Traceback (most recent call last):
  File "/usr/local/lib/python3.7/site-packages/telegram/ext/dispatcher.py", line 279, in process_update
    handler.handle_update(update, self)
  File "/usr/local/lib/python3.7/site-packages/telegram/ext/commandhandler.py", line 173, in handle_update
    return self.callback(dispatcher.bot, update, **optional_args)
  File "/Users/logan/PycharmProjects/MonopolyTelegramBot/telegram_interaction.py", line 315, in end_turn_handler
    game.end_turn(user_id)
  File "/Users/logan/PycharmProjects/MonopolyTelegramBot/monopoly.py", line 427, in end_turn
    self.players.get(self.turn).get_name())
AttributeError: 'NoneType' object has no attribute 'get_name'
2019-09-07 11:29:29,061 - telegram.ext.dispatcher - ERROR - An uncaught error was raised while processing the update
Traceback (most recent call last):
  File "/usr/local/lib/python3.7/site-packages/telegram/ext/dispatcher.py", line 279, in process_update
    handler.handle_update(update, self)
  File "/usr/local/lib/python3.7/site-packages/telegram/ext/commandhandler.py", line 173, in handle_update
    return self.callback(dispatcher.bot, update, **optional_args)
  File "/Users/logan/PycharmProjects/MonopolyTelegramBot/telegram_interaction.py", line 315, in end_turn_handler
    game.end_turn(user_id)
  File "/Users/logan/PycharmProjects/MonopolyTelegramBot/monopoly.py", line 427, in end_turn
    self.players.get(self.turn).get_name())
AttributeError: 'NoneType' object has no attribute 'get_name'
2019-09-07 11:30:16,961 - telegram.ext.dispatcher - ERROR - An uncaught error was raised while processing the update
Traceback (most recent call last):
  File "/usr/local/lib/python3.7/site-packages/telegram/ext/dispatcher.py", line 279, in process_update
    handler.handle_update(update, self)
  File "/usr/local/lib/python3.7/site-packages/telegram/ext/commandhandler.py", line 173, in handle_update
    return self.callback(dispatcher.bot, update, **optional_args)
  File "/Users/logan/PycharmProjects/MonopolyTelegramBot/telegram_interaction.py", line 500, in blame_handler
    if game.get_players()[game.turn].get_user_id() == user_id:
KeyError: 1
2019-09-07 11:31:11,947 - telegram.ext.dispatcher - ERROR - An uncaught error was raised while processing the update
Traceback (most recent call last):
  File "/usr/local/lib/python3.7/site-packages/telegram/ext/dispatcher.py", line 279, in process_update
    handler.handle_update(update, self)
  File "/usr/local/lib/python3.7/site-packages/telegram/ext/commandhandler.py", line 173, in handle_update
    return self.callback(dispatcher.bot, update, **optional_args)
  File "/Users/logan/PycharmProjects/MonopolyTelegramBot/telegram_interaction.py", line 315, in end_turn_handler
    game.end_turn(user_id)
  File "/Users/logan/PycharmProjects/MonopolyTelegramBot/monopoly.py", line 427, in end_turn
AttributeError: 'NoneType' object has no attribute 'get_name'
2019-09-07 11:31:20,034 - telegram.ext.dispatcher - ERROR - An uncaught error was raised while processing the update
Traceback (most recent call last):
  File "/usr/local/lib/python3.7/site-packages/telegram/ext/dispatcher.py", line 279, in process_update
    handler.handle_update(update, self)
  File "/usr/local/lib/python3.7/site-packages/telegram/ext/commandhandler.py", line 173, in handle_update
    return self.callback(dispatcher.bot, update, **optional_args)
  File "/Users/logan/PycharmProjects/MonopolyTelegramBot/telegram_interaction.py", line 315, in end_turn_handler
    game.end_turn(user_id)
  File "/Users/logan/PycharmProjects/MonopolyTelegramBot/monopoly.py", line 427, in end_turn
AttributeError: 'NoneType' object has no attribute 'get_name'
2019-09-07 11:31:35,873 - telegram.ext.dispatcher - ERROR - An uncaught error was raised while processing the update
Traceback (most recent call last):
  File "/usr/local/lib/python3.7/site-packages/telegram/ext/dispatcher.py", line 279, in process_update
    handler.handle_update(update, self)
  File "/usr/local/lib/python3.7/site-packages/telegram/ext/commandhandler.py", line 173, in handle_update
    return self.callback(dispatcher.bot, update, **optional_args)
  File "/Users/logan/PycharmProjects/MonopolyTelegramBot/telegram_interaction.py", line 315, in end_turn_handler
    game.end_turn(user_id)
  File "/Users/logan/PycharmProjects/MonopolyTelegramBot/monopoly.py", line 427, in end_turn
AttributeError: 'NoneType' object has no attribute 'get_name'
2019-09-07 11:31:52,609 - telegram.ext.dispatcher - ERROR - An uncaught error was raised while processing the update
Traceback (most recent call last):
  File "/usr/local/lib/python3.7/site-packages/telegram/ext/dispatcher.py", line 279, in process_update
    handler.handle_update(update, self)
  File "/usr/local/lib/python3.7/site-packages/telegram/ext/commandhandler.py", line 173, in handle_update
    return self.callback(dispatcher.bot, update, **optional_args)
  File "/Users/logan/PycharmProjects/MonopolyTelegramBot/telegram_interaction.py", line 315, in end_turn_handler
    game.end_turn(user_id)
  File "/Users/logan/PycharmProjects/MonopolyTelegramBot/monopoly.py", line 427, in end_turn
AttributeError: 'NoneType' object has no attribute 'get_name'
2019-09-07 11:31:57,808 - telegram.ext.dispatcher - ERROR - An uncaught error was raised while processing the update
Traceback (most recent call last):
  File "/usr/local/lib/python3.7/site-packages/telegram/ext/dispatcher.py", line 279, in process_update
    handler.handle_update(update, self)
  File "/usr/local/lib/python3.7/site-packages/telegram/ext/commandhandler.py", line 173, in handle_update
    return self.callback(dispatcher.bot, update, **optional_args)
  File "/Users/logan/PycharmProjects/MonopolyTelegramBot/telegram_interaction.py", line 315, in end_turn_handler
    game.end_turn(user_id)
  File "/Users/logan/PycharmProjects/MonopolyTelegramBot/monopoly.py", line 427, in end_turn
AttributeError: 'NoneType' object has no attribute 'get_name'
2019-09-07 11:34:35,156 - telegram.ext.dispatcher - ERROR - An uncaught error was raised while processing the update
Traceback (most recent call last):
  File "/usr/local/lib/python3.7/site-packages/telegram/ext/dispatcher.py", line 279, in process_update
    handler.handle_update(update, self)
  File "/usr/local/lib/python3.7/site-packages/telegram/ext/commandhandler.py", line 173, in handle_update
    return self.callback(dispatcher.bot, update, **optional_args)
  File "/Users/logan/PycharmProjects/MonopolyTelegramBot/telegram_interaction.py", line 315, in end_turn_handler
    game.end_turn(user_id)
  File "/Users/logan/PycharmProjects/MonopolyTelegramBot/monopoly.py", line 427, in end_turn
AttributeError: 'NoneType' object has no attribute 'get_name'
2019-09-07 11:37:09,644 - telegram.ext.dispatcher - ERROR - An uncaught error was raised while processing the update
Traceback (most recent call last):
  File "/usr/local/lib/python3.7/site-packages/telegram/ext/dispatcher.py", line 279, in process_update
    handler.handle_update(update, self)
  File "/usr/local/lib/python3.7/site-packages/telegram/ext/commandhandler.py", line 173, in handle_update
    return self.callback(dispatcher.bot, update, **optional_args)
  File "/Users/logan/PycharmProjects/MonopolyTelegramBot/telegram_interaction.py", line 315, in end_turn_handler
    game.end_turn(user_id)
  File "/Users/logan/PycharmProjects/MonopolyTelegramBot/monopoly.py", line 427, in end_turn
AttributeError: 'NoneType' object has no attribute 'get_name'
2019-09-07 11:37:18,116 - telegram.ext.dispatcher - ERROR - An uncaught error was raised while processing the update
Traceback (most recent call last):
  File "/usr/local/lib/python3.7/site-packages/telegram/ext/dispatcher.py", line 279, in process_update
    handler.handle_update(update, self)
  File "/usr/local/lib/python3.7/site-packages/telegram/ext/commandhandler.py", line 173, in handle_update
    return self.callback(dispatcher.bot, update, **optional_args)
  File "/Users/logan/PycharmProjects/MonopolyTelegramBot/telegram_interaction.py", line 315, in end_turn_handler
    game.end_turn(user_id)
  File "/Users/logan/PycharmProjects/MonopolyTelegramBot/monopoly.py", line 427, in end_turn
AttributeError: 'NoneType' object has no attribute 'get_name'
2019-09-07 11:37:48,048 - telegram.ext.dispatcher - ERROR - An uncaught error was raised while processing the update
Traceback (most recent call last):
  File "/usr/local/lib/python3.7/site-packages/telegram/ext/dispatcher.py", line 279, in process_update
    handler.handle_update(update, self)
  File "/usr/local/lib/python3.7/site-packages/telegram/ext/commandhandler.py", line 173, in handle_update
    return self.callback(dispatcher.bot, update, **optional_args)
  File "/Users/logan/PycharmProjects/MonopolyTelegramBot/telegram_interaction.py", line 333, in pay_handler
    game.pay(user_id, int(args[0]), int(args[1]))
ValueError: invalid literal for int() with base 10: '“bank”'
2019-09-07 11:39:31,566 - telegram.ext.updater - INFO - Received signal 2 (SIGINT), stopping...
2019-09-07 11:50:07,085 - telegram.ext.dispatcher - ERROR - An uncaught error was raised while processing the update
Traceback (most recent call last):
  File "/usr/local/lib/python3.7/site-packages/telegram/ext/dispatcher.py", line 279, in process_update
    handler.handle_update(update, self)
  File "/usr/local/lib/python3.7/site-packages/telegram/ext/commandhandler.py", line 173, in handle_update
    return self.callback(dispatcher.bot, update, **optional_args)
  File "/Users/logan/PycharmProjects/MonopolyTelegramBot/telegram_interaction.py", line 355, in bail_handler
    game.pay_bail(user_id)
  File "/Users/logan/PycharmProjects/MonopolyTelegramBot/monopoly.py", line 330, in pay_bail
    if player.get_total_assets() < 50:
  File "/Users/logan/PycharmProjects/MonopolyTelegramBot/monopoly.py", line 106, in get_total_assets
    total += (p.mortgage_value if p.get_mortgaged() else 0)
AttributeError: 'OtherProperty' object has no attribute 'get_mortgaged'
2019-09-07 11:50:21,269 - telegram.ext.dispatcher - ERROR - An uncaught error was raised while processing the update
Traceback (most recent call last):
  File "/usr/local/lib/python3.7/site-packages/telegram/ext/dispatcher.py", line 279, in process_update
    handler.handle_update(update, self)
  File "/usr/local/lib/python3.7/site-packages/telegram/ext/commandhandler.py", line 173, in handle_update
    return self.callback(dispatcher.bot, update, **optional_args)
  File "/Users/logan/PycharmProjects/MonopolyTelegramBot/telegram_interaction.py", line 355, in bail_handler
    game.pay_bail(user_id)
  File "/Users/logan/PycharmProjects/MonopolyTelegramBot/monopoly.py", line 330, in pay_bail
    if player.get_total_assets() < 50:
  File "/Users/logan/PycharmProjects/MonopolyTelegramBot/monopoly.py", line 106, in get_total_assets
    total += (p.mortgage_value if p.get_mortgaged() else 0)
AttributeError: 'OtherProperty' object has no attribute 'get_mortgaged'
2019-09-07 11:51:58,825 - telegram.ext.dispatcher - ERROR - An uncaught error was raised while processing the update
Traceback (most recent call last):
  File "/usr/local/lib/python3.7/site-packages/telegram/ext/dispatcher.py", line 279, in process_update
    handler.handle_update(update, self)
  File "/usr/local/lib/python3.7/site-packages/telegram/ext/commandhandler.py", line 173, in handle_update
    return self.callback(dispatcher.bot, update, **optional_args)
  File "/Users/logan/PycharmProjects/MonopolyTelegramBot/telegram_interaction.py", line 355, in bail_handler
    game.pay_bail(user_id)
  File "/Users/logan/PycharmProjects/MonopolyTelegramBot/monopoly.py", line 330, in pay_bail
    if player.get_money() < 50:
  File "/Users/logan/PycharmProjects/MonopolyTelegramBot/monopoly.py", line 106, in get_total_assets
    total += (p.mortgage_value if p.get_mortgaged() else 0)
AttributeError: 'OtherProperty' object has no attribute 'get_mortgaged'
2019-09-07 11:55:48,608 - telegram.ext.dispatcher - ERROR - An uncaught error was raised while processing the update
Traceback (most recent call last):
  File "/usr/local/lib/python3.7/site-packages/telegram/ext/dispatcher.py", line 279, in process_update
    handler.handle_update(update, self)
  File "/usr/local/lib/python3.7/site-packages/telegram/ext/commandhandler.py", line 173, in handle_update
    return self.callback(dispatcher.bot, update, **optional_args)
  File "/Users/logan/PycharmProjects/MonopolyTelegramBot/telegram_interaction.py", line 355, in bail_handler
    game.pay_bail(user_id)
  File "/Users/logan/PycharmProjects/MonopolyTelegramBot/monopoly.py", line 330, in pay_bail
    if player.get_turns_left_in_jail() == -1:
  File "/Users/logan/PycharmProjects/MonopolyTelegramBot/monopoly.py", line 106, in get_total_assets
    total += (p.mortgage_value if p.get_mortgaged() else 0)
AttributeError: 'OtherProperty' object has no attribute 'get_mortgaged'
2019-09-07 12:00:11,923 - telegram.vendor.ptb_urllib3.urllib3.connectionpool - WARNING - Retrying (Retry(total=2, connect=None, read=None, redirect=None)) after connection broken by 'ConnectTimeoutError(<telegram.vendor.ptb_urllib3.urllib3.connection.VerifiedHTTPSConnection object at 0x110129c50>, 'Connection to api.telegram.org timed out. (connect timeout=5.0)')': /bot854076226:AAGBGAeMq3le6mU2FpKcONa2b88D6A2-SzU/getUpdates
2019-09-07 12:02:30,865 - telegram.ext.dispatcher - ERROR - An uncaught error was raised while processing the update
Traceback (most recent call last):
  File "/usr/local/lib/python3.7/site-packages/telegram/ext/dispatcher.py", line 279, in process_update
    handler.handle_update(update, self)
  File "/usr/local/lib/python3.7/site-packages/telegram/ext/commandhandler.py", line 173, in handle_update
    return self.callback(dispatcher.bot, update, **optional_args)
  File "/Users/logan/PycharmProjects/MonopolyTelegramBot/telegram_interaction.py", line 355, in bail_handler
    game.pay_bail(user_id)
  File "/Users/logan/PycharmProjects/MonopolyTelegramBot/monopoly.py", line 330, in pay_bail
    if player.get_turns_left_in_jail() == -1:
  File "/Users/logan/PycharmProjects/MonopolyTelegramBot/monopoly.py", line 106, in get_total_assets
    total += (p.mortgage_value if p.get_mortgaged() else 0)
AttributeError: 'OtherProperty' object has no attribute 'get_mortgaged'
2019-09-07 12:17:00,201 - telegram.ext.dispatcher - ERROR - An uncaught error was raised while processing the update
Traceback (most recent call last):
  File "/usr/local/lib/python3.7/site-packages/telegram/ext/dispatcher.py", line 279, in process_update
    handler.handle_update(update, self)
  File "/usr/local/lib/python3.7/site-packages/telegram/ext/commandhandler.py", line 173, in handle_update
    return self.callback(dispatcher.bot, update, **optional_args)
  File "/Users/logan/PycharmProjects/MonopolyTelegramBot/telegram_interaction.py", line 370, in mortgage_handler
    game.mortgage_property(user_id, int(" ".join(args)))
  File "/Users/logan/PycharmProjects/MonopolyTelegramBot/monopoly.py", line 472, in mortgage_property
    return
AttributeError: 'Property' object has no attribute 'get_mortgage_value'
2019-09-07 12:23:05,440 - telegram.ext.updater - INFO - Received signal 2 (SIGINT), stopping...
2019-09-10 14:37:33,508 - telegram.ext.dispatcher - ERROR - An uncaught error was raised while processing the update
Traceback (most recent call last):
  File "/usr/local/lib/python3.7/site-packages/telegram/ext/dispatcher.py", line 279, in process_update
    handler.handle_update(update, self)
  File "/usr/local/lib/python3.7/site-packages/telegram/ext/commandhandler.py", line 173, in handle_update
    return self.callback(dispatcher.bot, update, **optional_args)
  File "/Users/logan/PycharmProjects/MonopolyTelegramBot/telegram_interaction.py", line 143, in listplayers_handler
    text += "(" + str(game.get_players[user_id].get_id()) + ") " + name + "\n"
TypeError: 'method' object is not subscriptable
2019-09-10 15:09:39,266 - telegram.ext.dispatcher - ERROR - An uncaught error was raised while processing the update
Traceback (most recent call last):
  File "/usr/local/lib/python3.7/site-packages/telegram/ext/dispatcher.py", line 279, in process_update
    handler.handle_update(update, self)
  File "/usr/local/lib/python3.7/site-packages/telegram/ext/commandhandler.py", line 173, in handle_update
    return self.callback(dispatcher.bot, update, **optional_args)
  File "/Users/logan/PycharmProjects/MonopolyTelegramBot/telegram_interaction.py", line 370, in mortgage_handler
  File "/Users/logan/PycharmProjects/MonopolyTelegramBot/monopoly.py", line 485, in mortgage_property
    mortgage_value += property.get_hotels() * property.get_hotel_cost()
AttributeError: 'Property' object has no attribute 'get_hotel_cost'
2019-09-10 15:19:05,898 - telegram.ext.dispatcher - WARNING - A TelegramError was raised while processing the Update
2019-09-10 15:19:05,898 - __main__ - WARNING - Telegram Error! Timed out caused by this update: {'update_id': 77920181, 'message': {'message_id': 3808, 'date': 1568143139, 'chat': {'id': -282831889, 'type': 'group', 'title': 'Monopoly', 'all_members_are_administrators': True}, 'text': '/bankrupt 2', 'entities': [{'type': 'bot_command', 'offset': 0, 'length': 9}], 'caption_entities': [], 'photo': [], 'new_chat_members': [], 'new_chat_photo': [], 'delete_chat_photo': False, 'group_chat_created': False, 'supergroup_chat_created': False, 'channel_chat_created': False, 'from': {'id': 539621524, 'first_name': 'Logan', 'is_bot': False, 'last_name': 'Apple', 'username': 'thweaver', 'language_code': 'en'}}, '_effective_user': {'id': 539621524, 'first_name': 'Logan', 'is_bot': False, 'last_name': 'Apple', 'username': 'thweaver', 'language_code': 'en'}, '_effective_chat': {'id': -282831889, 'type': 'group', 'title': 'Monopoly', 'all_members_are_administrators': True}}
2019-09-10 15:21:07,313 - telegram.ext.dispatcher - ERROR - An uncaught error was raised while processing the update
Traceback (most recent call last):
  File "/usr/local/lib/python3.7/site-packages/telegram/ext/dispatcher.py", line 279, in process_update
    handler.handle_update(update, self)
  File "/usr/local/lib/python3.7/site-packages/telegram/ext/commandhandler.py", line 173, in handle_update
    return self.callback(dispatcher.bot, update, **optional_args)
  File "/Users/logan/PycharmProjects/MonopolyTelegramBot/telegram_interaction.py", line 256, in bankrupt_handler
  File "/Users/logan/PycharmProjects/MonopolyTelegramBot/monopoly.py", line 1136, in bankrupt
    if player_2 is None:
KeyError: 539621524
2019-09-10 15:21:38,567 - telegram.ext.dispatcher - ERROR - An uncaught error was raised while processing the update
Traceback (most recent call last):
  File "/usr/local/lib/python3.7/site-packages/telegram/ext/dispatcher.py", line 279, in process_update
    handler.handle_update(update, self)
  File "/usr/local/lib/python3.7/site-packages/telegram/ext/commandhandler.py", line 173, in handle_update
    return self.callback(dispatcher.bot, update, **optional_args)
  File "/Users/logan/PycharmProjects/MonopolyTelegramBot/telegram_interaction.py", line 500, in blame_handler
    for user_id, player in game.get_players().items():
AttributeError: 'NoneType' object has no attribute 'get_user_id'
2019-09-10 15:21:47,429 - telegram.ext.dispatcher - ERROR - An uncaught error was raised while processing the update
Traceback (most recent call last):
  File "/usr/local/lib/python3.7/site-packages/telegram/ext/dispatcher.py", line 279, in process_update
    handler.handle_update(update, self)
  File "/usr/local/lib/python3.7/site-packages/telegram/ext/commandhandler.py", line 173, in handle_update
    return self.callback(dispatcher.bot, update, **optional_args)
  File "/Users/logan/PycharmProjects/MonopolyTelegramBot/telegram_interaction.py", line 500, in blame_handler
    for user_id, player in game.get_players().items():
AttributeError: 'NoneType' object has no attribute 'get_user_id'
2019-09-10 15:31:25,238 - telegram.ext.updater - INFO - Received signal 2 (SIGINT), stopping...
2019-09-10 15:41:27,233 - telegram.ext.dispatcher - ERROR - An uncaught error was raised while processing the update
Traceback (most recent call last):
  File "/usr/local/lib/python3.7/site-packages/telegram/ext/dispatcher.py", line 279, in process_update
    handler.handle_update(update, self)
  File "/usr/local/lib/python3.7/site-packages/telegram/ext/commandhandler.py", line 173, in handle_update
    return self.callback(dispatcher.bot, update, **optional_args)
  File "/Users/logan/PycharmProjects/MonopolyTelegramBot/telegram_interaction.py", line 519, in assets_handler
    send_info(bot, chat_id, game, user_id)
  File "/Users/logan/PycharmProjects/MonopolyTelegramBot/telegram_interaction.py", line 44, in send_info
    props = player.get_properties_str()
  File "/Users/logan/PycharmProjects/MonopolyTelegramBot/monopoly.py", line 89, in get_properties_str
    " (" + p.get_houses() + " houses, " + p.get_hotels() + " hotels)\n"
TypeError: can only concatenate str (not "int") to str
2019-09-10 15:41:53,185 - telegram.ext.updater - INFO - Received signal 2 (SIGINT), stopping...
2019-09-10 16:19:42,844 - telegram.ext.dispatcher - ERROR - An uncaught error was raised while processing the update
Traceback (most recent call last):
  File "/usr/local/lib/python3.7/site-packages/telegram/ext/dispatcher.py", line 279, in process_update
    handler.handle_update(update, self)
  File "/usr/local/lib/python3.7/site-packages/telegram/ext/commandhandler.py", line 173, in handle_update
    return self.callback(dispatcher.bot, update, **optional_args)
  File "/Users/logan/PycharmProjects/MonopolyTelegramBot/telegram_interaction.py", line 244, in roll_handler
    game.roll_dice(user_id)
  File "/Users/logan/PycharmProjects/MonopolyTelegramBot/monopoly.py", line 1275, in roll_dice
    self.check_pass_go("passed", last_total_roll, current_total_roll, player)
  File "/Users/logan/PycharmProjects/MonopolyTelegramBot/monopoly.py", line 1144, in enact_roll_result
  File "/Users/logan/PycharmProjects/MonopolyTelegramBot/monopoly.py", line 1097, in cc_result
    owed = 0
AttributeError: 'OtherProperty' object has no attribute 'get_houses'
2019-09-10 16:50:58,935 - telegram.ext.updater - INFO - Received signal 2 (SIGINT), stopping...
2019-09-12 22:10:31,009 - telegram.ext.updater - INFO - Received signal 2 (SIGINT), stopping...
2019-09-13 12:14:41,495 - telegram.ext.dispatcher - ERROR - An uncaught error was raised while processing the update
Traceback (most recent call last):
  File "/usr/local/lib/python3.7/site-packages/telegram/ext/dispatcher.py", line 279, in process_update
    handler.handle_update(update, self)
  File "/usr/local/lib/python3.7/site-packages/telegram/ext/commandhandler.py", line 173, in handle_update
    return self.callback(dispatcher.bot, update, **optional_args)
  File "/Users/logan/PycharmProjects/MonopolyTelegramBot/telegram_interaction.py", line 516, in assets_handler
    send_info(bot, chat_id, game, user_id)
  File "/Users/logan/PycharmProjects/MonopolyTelegramBot/telegram_interaction.py", line 44, in send_info
    props = player.get_properties_str()
  File "/Users/logan/PycharmProjects/MonopolyTelegramBot/monopoly.py", line 90, in get_properties_str
    " [Mortgage Value: " + p.get_mortgage_value() + "] " + \
TypeError: can only concatenate str (not "int") to str
2019-09-13 12:14:49,293 - telegram.ext.dispatcher - ERROR - An uncaught error was raised while processing the update
Traceback (most recent call last):
  File "/usr/local/lib/python3.7/site-packages/telegram/ext/dispatcher.py", line 279, in process_update
    handler.handle_update(update, self)
  File "/usr/local/lib/python3.7/site-packages/telegram/ext/commandhandler.py", line 173, in handle_update
    return self.callback(dispatcher.bot, update, **optional_args)
  File "/Users/logan/PycharmProjects/MonopolyTelegramBot/telegram_interaction.py", line 337, in purchase_property_handler
    game.purchase_property(user_id)
  File "/Users/logan/PycharmProjects/MonopolyTelegramBot/monopoly.py", line 492, in purchase_property
    player.sort_props_by_color()
  File "/Users/logan/PycharmProjects/MonopolyTelegramBot/monopoly.py", line 127, in sort_props_by_color
    self.properties.sort(key=lambda p: p.get_color())
  File "/Users/logan/PycharmProjects/MonopolyTelegramBot/monopoly.py", line 127, in <lambda>
    self.properties.sort(key=lambda p: p.get_color())
AttributeError: 'OtherProperty' object has no attribute 'get_color'
2019-09-13 12:14:59,210 - telegram.ext.dispatcher - ERROR - An uncaught error was raised while processing the update
Traceback (most recent call last):
  File "/usr/local/lib/python3.7/site-packages/telegram/ext/dispatcher.py", line 279, in process_update
    handler.handle_update(update, self)
  File "/usr/local/lib/python3.7/site-packages/telegram/ext/commandhandler.py", line 173, in handle_update
    return self.callback(dispatcher.bot, update, **optional_args)
  File "/Users/logan/PycharmProjects/MonopolyTelegramBot/telegram_interaction.py", line 516, in assets_handler
    send_info(bot, chat_id, game, user_id)
  File "/Users/logan/PycharmProjects/MonopolyTelegramBot/telegram_interaction.py", line 44, in send_info
    props = player.get_properties_str()
  File "/Users/logan/PycharmProjects/MonopolyTelegramBot/monopoly.py", line 94, in get_properties_str
    " [Mortgage Value: " + p.get_mortgage_value() + "] " + \
TypeError: can only concatenate str (not "int") to str
2019-09-13 12:15:09,480 - telegram.ext.updater - INFO - Received signal 2 (SIGINT), stopping...
2019-09-13 12:16:47,694 - telegram.ext.dispatcher - ERROR - An uncaught error was raised while processing the update
Traceback (most recent call last):
  File "/usr/local/lib/python3.7/site-packages/telegram/ext/dispatcher.py", line 279, in process_update
    handler.handle_update(update, self)
  File "/usr/local/lib/python3.7/site-packages/telegram/ext/commandhandler.py", line 173, in handle_update
    return self.callback(dispatcher.bot, update, **optional_args)
  File "/Users/logan/PycharmProjects/MonopolyTelegramBot/telegram_interaction.py", line 337, in purchase_property_handler
    game.purchase_property(user_id)
  File "/Users/logan/PycharmProjects/MonopolyTelegramBot/monopoly.py", line 492, in purchase_property
    player.sort_props_by_color()
  File "/Users/logan/PycharmProjects/MonopolyTelegramBot/monopoly.py", line 127, in sort_props_by_color
    self.properties.sort(key=lambda p: p.get_color())
  File "/Users/logan/PycharmProjects/MonopolyTelegramBot/monopoly.py", line 127, in <lambda>
    self.properties.sort(key=lambda p: p.get_color())
AttributeError: 'OtherProperty' object has no attribute 'get_color'
2019-09-13 12:17:31,824 - telegram.ext.dispatcher - ERROR - An uncaught error was raised while processing the update
Traceback (most recent call last):
  File "/usr/local/lib/python3.7/site-packages/telegram/ext/dispatcher.py", line 279, in process_update
    handler.handle_update(update, self)
  File "/usr/local/lib/python3.7/site-packages/telegram/ext/commandhandler.py", line 173, in handle_update
    return self.callback(dispatcher.bot, update, **optional_args)
  File "/Users/logan/PycharmProjects/MonopolyTelegramBot/telegram_interaction.py", line 337, in purchase_property_handler
    game.purchase_property(user_id)
  File "/Users/logan/PycharmProjects/MonopolyTelegramBot/monopoly.py", line 492, in purchase_property
    player.sort_props_by_color()
  File "/Users/logan/PycharmProjects/MonopolyTelegramBot/monopoly.py", line 127, in sort_props_by_color
    self.properties.sort(key=lambda p: p.get_color())
  File "/Users/logan/PycharmProjects/MonopolyTelegramBot/monopoly.py", line 127, in <lambda>
    self.properties.sort(key=lambda p: p.get_color())
AttributeError: 'OtherProperty' object has no attribute 'get_color'
2019-09-13 12:18:09,211 - telegram.ext.dispatcher - ERROR - An uncaught error was raised while processing the update
Traceback (most recent call last):
  File "/usr/local/lib/python3.7/site-packages/telegram/ext/dispatcher.py", line 279, in process_update
    handler.handle_update(update, self)
  File "/usr/local/lib/python3.7/site-packages/telegram/ext/commandhandler.py", line 173, in handle_update
    return self.callback(dispatcher.bot, update, **optional_args)
  File "/Users/logan/PycharmProjects/MonopolyTelegramBot/telegram_interaction.py", line 337, in purchase_property_handler
    game.purchase_property(user_id)
  File "/Users/logan/PycharmProjects/MonopolyTelegramBot/monopoly.py", line 492, in purchase_property
    player.sort_props_by_color()
  File "/Users/logan/PycharmProjects/MonopolyTelegramBot/monopoly.py", line 127, in sort_props_by_color
    self.properties.sort(key=lambda p: p.get_color())
  File "/Users/logan/PycharmProjects/MonopolyTelegramBot/monopoly.py", line 127, in <lambda>
    self.properties.sort(key=lambda p: p.get_color())
AttributeError: 'OtherProperty' object has no attribute 'get_color'
2019-09-13 12:18:58,540 - telegram.ext.dispatcher - ERROR - An uncaught error was raised while processing the update
Traceback (most recent call last):
  File "/usr/local/lib/python3.7/site-packages/telegram/ext/dispatcher.py", line 279, in process_update
    handler.handle_update(update, self)
  File "/usr/local/lib/python3.7/site-packages/telegram/ext/commandhandler.py", line 173, in handle_update
    return self.callback(dispatcher.bot, update, **optional_args)
  File "/Users/logan/PycharmProjects/MonopolyTelegramBot/telegram_interaction.py", line 337, in purchase_property_handler
    game.purchase_property(user_id)
  File "/Users/logan/PycharmProjects/MonopolyTelegramBot/monopoly.py", line 492, in purchase_property
    player.sort_props_by_color()
  File "/Users/logan/PycharmProjects/MonopolyTelegramBot/monopoly.py", line 127, in sort_props_by_color
    self.properties.sort(key=lambda p: p.get_color())
  File "/Users/logan/PycharmProjects/MonopolyTelegramBot/monopoly.py", line 127, in <lambda>
    self.properties.sort(key=lambda p: p.get_color())
AttributeError: 'OtherProperty' object has no attribute 'get_color'
2019-09-13 12:21:36,391 - telegram.ext.dispatcher - ERROR - An uncaught error was raised while processing the update
Traceback (most recent call last):
  File "/usr/local/lib/python3.7/site-packages/telegram/ext/dispatcher.py", line 279, in process_update
    handler.handle_update(update, self)
  File "/usr/local/lib/python3.7/site-packages/telegram/ext/commandhandler.py", line 173, in handle_update
    return self.callback(dispatcher.bot, update, **optional_args)
  File "/Users/logan/PycharmProjects/MonopolyTelegramBot/telegram_interaction.py", line 337, in purchase_property_handler
    game.purchase_property(user_id)
  File "/Users/logan/PycharmProjects/MonopolyTelegramBot/monopoly.py", line 492, in purchase_property
    player.sort_props_by_color()
  File "/Users/logan/PycharmProjects/MonopolyTelegramBot/monopoly.py", line 127, in sort_props_by_color
    self.properties.sort(key=lambda p: p.get_color())
  File "/Users/logan/PycharmProjects/MonopolyTelegramBot/monopoly.py", line 127, in <lambda>
    self.properties.sort(key=lambda p: p.get_color())
AttributeError: 'OtherProperty' object has no attribute 'get_color'
2019-09-13 12:21:44,904 - telegram.ext.dispatcher - ERROR - An uncaught error was raised while processing the update
Traceback (most recent call last):
  File "/usr/local/lib/python3.7/site-packages/telegram/ext/dispatcher.py", line 279, in process_update
    handler.handle_update(update, self)
  File "/usr/local/lib/python3.7/site-packages/telegram/ext/commandhandler.py", line 173, in handle_update
    return self.callback(dispatcher.bot, update, **optional_args)
  File "/Users/logan/PycharmProjects/MonopolyTelegramBot/telegram_interaction.py", line 337, in purchase_property_handler
    game.purchase_property(user_id)
  File "/Users/logan/PycharmProjects/MonopolyTelegramBot/monopoly.py", line 492, in purchase_property
    player.sort_props_by_color()
  File "/Users/logan/PycharmProjects/MonopolyTelegramBot/monopoly.py", line 127, in sort_props_by_color
    self.properties.sort(key=lambda p: p.get_color())
  File "/Users/logan/PycharmProjects/MonopolyTelegramBot/monopoly.py", line 127, in <lambda>
    self.properties.sort(key=lambda p: p.get_color())
AttributeError: 'OtherProperty' object has no attribute 'get_color'
2019-09-13 12:21:54,080 - telegram.ext.dispatcher - ERROR - An uncaught error was raised while processing the update
Traceback (most recent call last):
  File "/usr/local/lib/python3.7/site-packages/telegram/ext/dispatcher.py", line 279, in process_update
    handler.handle_update(update, self)
  File "/usr/local/lib/python3.7/site-packages/telegram/ext/commandhandler.py", line 173, in handle_update
    return self.callback(dispatcher.bot, update, **optional_args)
  File "/Users/logan/PycharmProjects/MonopolyTelegramBot/telegram_interaction.py", line 337, in purchase_property_handler
    game.purchase_property(user_id)
  File "/Users/logan/PycharmProjects/MonopolyTelegramBot/monopoly.py", line 492, in purchase_property
    player.sort_props_by_color()
  File "/Users/logan/PycharmProjects/MonopolyTelegramBot/monopoly.py", line 127, in sort_props_by_color
    self.properties.sort(key=lambda p: p.get_color())
  File "/Users/logan/PycharmProjects/MonopolyTelegramBot/monopoly.py", line 127, in <lambda>
    self.properties.sort(key=lambda p: p.get_color())
AttributeError: 'OtherProperty' object has no attribute 'get_color'
2019-09-13 12:22:53,685 - telegram.ext.dispatcher - ERROR - An uncaught error was raised while processing the update
Traceback (most recent call last):
  File "/usr/local/lib/python3.7/site-packages/telegram/ext/dispatcher.py", line 279, in process_update
    handler.handle_update(update, self)
  File "/usr/local/lib/python3.7/site-packages/telegram/ext/commandhandler.py", line 173, in handle_update
    return self.callback(dispatcher.bot, update, **optional_args)
  File "/Users/logan/PycharmProjects/MonopolyTelegramBot/telegram_interaction.py", line 337, in purchase_property_handler
    game.purchase_property(user_id)
  File "/Users/logan/PycharmProjects/MonopolyTelegramBot/monopoly.py", line 492, in purchase_property
    player.sort_props_by_color()
  File "/Users/logan/PycharmProjects/MonopolyTelegramBot/monopoly.py", line 127, in sort_props_by_color
    self.properties.sort(key=lambda p: p.get_color())
  File "/Users/logan/PycharmProjects/MonopolyTelegramBot/monopoly.py", line 127, in <lambda>
    self.properties.sort(key=lambda p: p.get_color())
AttributeError: 'OtherProperty' object has no attribute 'get_color'
2019-09-13 12:23:43,621 - telegram.ext.dispatcher - ERROR - An uncaught error was raised while processing the update
Traceback (most recent call last):
  File "/usr/local/lib/python3.7/site-packages/telegram/ext/dispatcher.py", line 279, in process_update
    handler.handle_update(update, self)
  File "/usr/local/lib/python3.7/site-packages/telegram/ext/commandhandler.py", line 173, in handle_update
    return self.callback(dispatcher.bot, update, **optional_args)
  File "/Users/logan/PycharmProjects/MonopolyTelegramBot/telegram_interaction.py", line 337, in purchase_property_handler
    game.purchase_property(user_id)
  File "/Users/logan/PycharmProjects/MonopolyTelegramBot/monopoly.py", line 492, in purchase_property
    player.sort_props_by_color()
  File "/Users/logan/PycharmProjects/MonopolyTelegramBot/monopoly.py", line 127, in sort_props_by_color
    self.properties.sort(key=lambda p: p.get_color())
  File "/Users/logan/PycharmProjects/MonopolyTelegramBot/monopoly.py", line 127, in <lambda>
    self.properties.sort(key=lambda p: p.get_color())
AttributeError: 'OtherProperty' object has no attribute 'get_color'
2019-09-13 12:30:33,974 - telegram.ext.dispatcher - ERROR - An uncaught error was raised while processing the update
Traceback (most recent call last):
  File "/usr/local/lib/python3.7/site-packages/telegram/ext/dispatcher.py", line 279, in process_update
    handler.handle_update(update, self)
  File "/usr/local/lib/python3.7/site-packages/telegram/ext/commandhandler.py", line 173, in handle_update
    return self.callback(dispatcher.bot, update, **optional_args)
  File "/Users/logan/PycharmProjects/MonopolyTelegramBot/telegram_interaction.py", line 337, in purchase_property_handler
    game.purchase_property(user_id)
  File "/Users/logan/PycharmProjects/MonopolyTelegramBot/monopoly.py", line 492, in purchase_property
    player.add_money(-property_cost)
  File "/Users/logan/PycharmProjects/MonopolyTelegramBot/monopoly.py", line 127, in sort_props_by_color
    self.properties.sort(key=lambda p: p.get_color())
  File "/Users/logan/PycharmProjects/MonopolyTelegramBot/monopoly.py", line 127, in <lambda>
    self.properties.sort(key=lambda p: p.get_color())
AttributeError: 'OtherProperty' object has no attribute 'get_color'
2019-09-13 12:30:42,427 - telegram.ext.dispatcher - ERROR - An uncaught error was raised while processing the update
Traceback (most recent call last):
  File "/usr/local/lib/python3.7/site-packages/telegram/ext/dispatcher.py", line 279, in process_update
    handler.handle_update(update, self)
  File "/usr/local/lib/python3.7/site-packages/telegram/ext/commandhandler.py", line 173, in handle_update
    return self.callback(dispatcher.bot, update, **optional_args)
  File "/Users/logan/PycharmProjects/MonopolyTelegramBot/telegram_interaction.py", line 337, in purchase_property_handler
    game.purchase_property(user_id)
  File "/Users/logan/PycharmProjects/MonopolyTelegramBot/monopoly.py", line 492, in purchase_property
    player.add_money(-property_cost)
  File "/Users/logan/PycharmProjects/MonopolyTelegramBot/monopoly.py", line 127, in sort_props_by_color
    self.properties.sort(key=lambda p: p.get_color())
  File "/Users/logan/PycharmProjects/MonopolyTelegramBot/monopoly.py", line 127, in <lambda>
    self.properties.sort(key=lambda p: p.get_color())
AttributeError: 'OtherProperty' object has no attribute 'get_color'
2019-09-13 12:31:04,220 - telegram.ext.dispatcher - ERROR - An uncaught error was raised while processing the update
Traceback (most recent call last):
  File "/usr/local/lib/python3.7/site-packages/telegram/ext/dispatcher.py", line 279, in process_update
    handler.handle_update(update, self)
  File "/usr/local/lib/python3.7/site-packages/telegram/ext/commandhandler.py", line 173, in handle_update
    return self.callback(dispatcher.bot, update, **optional_args)
  File "/Users/logan/PycharmProjects/MonopolyTelegramBot/telegram_interaction.py", line 337, in purchase_property_handler
    game.purchase_property(user_id)
  File "/Users/logan/PycharmProjects/MonopolyTelegramBot/monopoly.py", line 492, in purchase_property
    player.add_money(-property_cost)
  File "/Users/logan/PycharmProjects/MonopolyTelegramBot/monopoly.py", line 127, in sort_props_by_color
    self.properties.sort(key=lambda p: p.get_color())
  File "/Users/logan/PycharmProjects/MonopolyTelegramBot/monopoly.py", line 127, in <lambda>
    self.properties.sort(key=lambda p: p.get_color())
AttributeError: 'OtherProperty' object has no attribute 'get_color'
2019-09-13 12:34:02,791 - telegram.ext.dispatcher - ERROR - An uncaught error was raised while processing the update
Traceback (most recent call last):
  File "/usr/local/lib/python3.7/site-packages/telegram/ext/dispatcher.py", line 279, in process_update
    handler.handle_update(update, self)
  File "/usr/local/lib/python3.7/site-packages/telegram/ext/commandhandler.py", line 173, in handle_update
    return self.callback(dispatcher.bot, update, **optional_args)
  File "/Users/logan/PycharmProjects/MonopolyTelegramBot/telegram_interaction.py", line 337, in purchase_property_handler
    game.purchase_property(user_id)
  File "/Users/logan/PycharmProjects/MonopolyTelegramBot/monopoly.py", line 492, in purchase_property
    player.add_money(-property_cost)
  File "/Users/logan/PycharmProjects/MonopolyTelegramBot/monopoly.py", line 127, in sort_props_by_color
    self.properties.sort(key=lambda p: p.get_color())
  File "/Users/logan/PycharmProjects/MonopolyTelegramBot/monopoly.py", line 127, in <lambda>
    self.properties.sort(key=lambda p: p.get_color())
AttributeError: 'OtherProperty' object has no attribute 'get_color'
2019-09-13 12:35:52,809 - telegram.ext.dispatcher - ERROR - An uncaught error was raised while processing the update
Traceback (most recent call last):
  File "/usr/local/lib/python3.7/site-packages/telegram/ext/dispatcher.py", line 279, in process_update
    handler.handle_update(update, self)
  File "/usr/local/lib/python3.7/site-packages/telegram/ext/commandhandler.py", line 173, in handle_update
    return self.callback(dispatcher.bot, update, **optional_args)
  File "/Users/logan/PycharmProjects/MonopolyTelegramBot/telegram_interaction.py", line 337, in purchase_property_handler
    game.purchase_property(user_id)
  File "/Users/logan/PycharmProjects/MonopolyTelegramBot/monopoly.py", line 492, in purchase_property
    player.add_money(-property_cost)
  File "/Users/logan/PycharmProjects/MonopolyTelegramBot/monopoly.py", line 127, in sort_props_by_color
    self.properties.sort(key=lambda p: p.get_color())
  File "/Users/logan/PycharmProjects/MonopolyTelegramBot/monopoly.py", line 127, in <lambda>
    self.properties.sort(key=lambda p: p.get_color())
AttributeError: 'OtherProperty' object has no attribute 'get_color'
2019-09-13 12:36:01,754 - telegram.ext.dispatcher - ERROR - An uncaught error was raised while processing the update
Traceback (most recent call last):
  File "/usr/local/lib/python3.7/site-packages/telegram/ext/dispatcher.py", line 279, in process_update
    handler.handle_update(update, self)
  File "/usr/local/lib/python3.7/site-packages/telegram/ext/commandhandler.py", line 173, in handle_update
    return self.callback(dispatcher.bot, update, **optional_args)
  File "/Users/logan/PycharmProjects/MonopolyTelegramBot/telegram_interaction.py", line 337, in purchase_property_handler
    game.purchase_property(user_id)
  File "/Users/logan/PycharmProjects/MonopolyTelegramBot/monopoly.py", line 492, in purchase_property
    player.add_money(-property_cost)
  File "/Users/logan/PycharmProjects/MonopolyTelegramBot/monopoly.py", line 127, in sort_props_by_color
    self.properties.sort(key=lambda p: p.get_color())
  File "/Users/logan/PycharmProjects/MonopolyTelegramBot/monopoly.py", line 127, in <lambda>
    self.properties.sort(key=lambda p: p.get_color())
AttributeError: 'OtherProperty' object has no attribute 'get_color'
2019-09-13 12:40:40,895 - telegram.ext.dispatcher - ERROR - An uncaught error was raised while processing the update
Traceback (most recent call last):
  File "/usr/local/lib/python3.7/site-packages/telegram/ext/dispatcher.py", line 279, in process_update
    handler.handle_update(update, self)
  File "/usr/local/lib/python3.7/site-packages/telegram/ext/commandhandler.py", line 173, in handle_update
    return self.callback(dispatcher.bot, update, **optional_args)
  File "/Users/logan/PycharmProjects/MonopolyTelegramBot/telegram_interaction.py", line 337, in purchase_property_handler
    game.purchase_property(user_id)
  File "/Users/logan/PycharmProjects/MonopolyTelegramBot/monopoly.py", line 492, in purchase_property
    player.add_money(-property_cost)
  File "/Users/logan/PycharmProjects/MonopolyTelegramBot/monopoly.py", line 127, in sort_props_by_color
    self.properties.sort(key=lambda p: p.get_color())
  File "/Users/logan/PycharmProjects/MonopolyTelegramBot/monopoly.py", line 127, in <lambda>
    self.properties.sort(key=lambda p: p.get_color())
AttributeError: 'OtherProperty' object has no attribute 'get_color'
2019-09-13 12:43:58,167 - telegram.ext.dispatcher - ERROR - An uncaught error was raised while processing the update
Traceback (most recent call last):
  File "/usr/local/lib/python3.7/site-packages/telegram/ext/dispatcher.py", line 279, in process_update
    handler.handle_update(update, self)
  File "/usr/local/lib/python3.7/site-packages/telegram/ext/commandhandler.py", line 173, in handle_update
    return self.callback(dispatcher.bot, update, **optional_args)
  File "/Users/logan/PycharmProjects/MonopolyTelegramBot/telegram_interaction.py", line 337, in purchase_property_handler
    game.purchase_property(user_id)
  File "/Users/logan/PycharmProjects/MonopolyTelegramBot/monopoly.py", line 492, in purchase_property
    player.add_money(-property_cost)
  File "/Users/logan/PycharmProjects/MonopolyTelegramBot/monopoly.py", line 127, in sort_props_by_color
    self.properties.sort(key=lambda p: p.get_color())
  File "/Users/logan/PycharmProjects/MonopolyTelegramBot/monopoly.py", line 127, in <lambda>
    self.properties.sort(key=lambda p: p.get_color())
AttributeError: 'OtherProperty' object has no attribute 'get_color'
2019-09-13 12:45:01,993 - telegram.ext.dispatcher - ERROR - An uncaught error was raised while processing the update
Traceback (most recent call last):
  File "/usr/local/lib/python3.7/site-packages/telegram/ext/dispatcher.py", line 279, in process_update
    handler.handle_update(update, self)
  File "/usr/local/lib/python3.7/site-packages/telegram/ext/commandhandler.py", line 173, in handle_update
    return self.callback(dispatcher.bot, update, **optional_args)
  File "/Users/logan/PycharmProjects/MonopolyTelegramBot/telegram_interaction.py", line 337, in purchase_property_handler
    game.purchase_property(user_id)
  File "/Users/logan/PycharmProjects/MonopolyTelegramBot/monopoly.py", line 492, in purchase_property
    player.add_money(-property_cost)
  File "/Users/logan/PycharmProjects/MonopolyTelegramBot/monopoly.py", line 127, in sort_props_by_color
    self.properties.sort(key=lambda p: p.get_color())
  File "/Users/logan/PycharmProjects/MonopolyTelegramBot/monopoly.py", line 127, in <lambda>
    self.properties.sort(key=lambda p: p.get_color())
AttributeError: 'OtherProperty' object has no attribute 'get_color'
2019-09-13 12:46:30,031 - telegram.ext.dispatcher - ERROR - An uncaught error was raised while processing the update
Traceback (most recent call last):
  File "/usr/local/lib/python3.7/site-packages/telegram/ext/dispatcher.py", line 279, in process_update
    handler.handle_update(update, self)
  File "/usr/local/lib/python3.7/site-packages/telegram/ext/commandhandler.py", line 173, in handle_update
    return self.callback(dispatcher.bot, update, **optional_args)
  File "/Users/logan/PycharmProjects/MonopolyTelegramBot/telegram_interaction.py", line 337, in purchase_property_handler
    game.purchase_property(user_id)
  File "/Users/logan/PycharmProjects/MonopolyTelegramBot/monopoly.py", line 492, in purchase_property
    player.add_money(-property_cost)
  File "/Users/logan/PycharmProjects/MonopolyTelegramBot/monopoly.py", line 127, in sort_props_by_color
    self.properties.sort(key=lambda p: p.get_color())
  File "/Users/logan/PycharmProjects/MonopolyTelegramBot/monopoly.py", line 127, in <lambda>
    self.properties.sort(key=lambda p: p.get_color())
AttributeError: 'OtherProperty' object has no attribute 'get_color'
2019-09-13 12:47:54,262 - telegram.ext.dispatcher - ERROR - An uncaught error was raised while processing the update
Traceback (most recent call last):
  File "/usr/local/lib/python3.7/site-packages/telegram/ext/dispatcher.py", line 279, in process_update
    handler.handle_update(update, self)
  File "/usr/local/lib/python3.7/site-packages/telegram/ext/commandhandler.py", line 173, in handle_update
    return self.callback(dispatcher.bot, update, **optional_args)
  File "/Users/logan/PycharmProjects/MonopolyTelegramBot/telegram_interaction.py", line 337, in purchase_property_handler
    game.purchase_property(user_id)
  File "/Users/logan/PycharmProjects/MonopolyTelegramBot/monopoly.py", line 492, in purchase_property
    player.add_money(-property_cost)
  File "/Users/logan/PycharmProjects/MonopolyTelegramBot/monopoly.py", line 127, in sort_props_by_color
    self.properties.sort(key=lambda p: p.get_color())
  File "/Users/logan/PycharmProjects/MonopolyTelegramBot/monopoly.py", line 127, in <lambda>
    self.properties.sort(key=lambda p: p.get_color())
AttributeError: 'OtherProperty' object has no attribute 'get_color'
2019-09-13 13:05:41,072 - telegram.ext.dispatcher - ERROR - An uncaught error was raised while processing the update
Traceback (most recent call last):
  File "/usr/local/lib/python3.7/site-packages/telegram/ext/dispatcher.py", line 279, in process_update
    handler.handle_update(update, self)
  File "/usr/local/lib/python3.7/site-packages/telegram/ext/commandhandler.py", line 173, in handle_update
    return self.callback(dispatcher.bot, update, **optional_args)
  File "/Users/logan/PycharmProjects/MonopolyTelegramBot/telegram_interaction.py", line 503, in setup_trade_handler
ValueError: invalid literal for int() with base 10: 'Logan'
2019-09-13 13:06:45,908 - telegram.ext.dispatcher - ERROR - An uncaught error was raised while processing the update
Traceback (most recent call last):
  File "/usr/local/lib/python3.7/site-packages/telegram/ext/dispatcher.py", line 279, in process_update
    handler.handle_update(update, self)
  File "/usr/local/lib/python3.7/site-packages/telegram/ext/commandhandler.py", line 173, in handle_update
    return self.callback(dispatcher.bot, update, **optional_args)
  File "/Users/logan/PycharmProjects/MonopolyTelegramBot/telegram_interaction.py", line 488, in trade_handler
  File "/Users/logan/PycharmProjects/MonopolyTelegramBot/monopoly.py", line 822, in trade
    if not bankrupt:
  File "/Users/logan/PycharmProjects/MonopolyTelegramBot/monopoly.py", line 127, in sort_props_by_color
    self.properties.sort(key=lambda p: p.get_color())
  File "/Users/logan/PycharmProjects/MonopolyTelegramBot/monopoly.py", line 127, in <lambda>
    self.properties.sort(key=lambda p: p.get_color())
AttributeError: 'OtherProperty' object has no attribute 'get_color'
2019-09-13 13:14:27,373 - telegram.ext.dispatcher - ERROR - An uncaught error was raised while processing the update
Traceback (most recent call last):
  File "/usr/local/lib/python3.7/site-packages/telegram/ext/dispatcher.py", line 279, in process_update
    handler.handle_update(update, self)
  File "/usr/local/lib/python3.7/site-packages/telegram/ext/commandhandler.py", line 173, in handle_update
    return self.callback(dispatcher.bot, update, **optional_args)
  File "/Users/logan/PycharmProjects/MonopolyTelegramBot/telegram_interaction.py", line 337, in purchase_property_handler
  File "/Users/logan/PycharmProjects/MonopolyTelegramBot/monopoly.py", line 492, in purchase_property
    player.add_money(-property_cost)
  File "/Users/logan/PycharmProjects/MonopolyTelegramBot/monopoly.py", line 127, in sort_props_by_color
    self.properties.sort(key=lambda p: p.get_color())
  File "/Users/logan/PycharmProjects/MonopolyTelegramBot/monopoly.py", line 127, in <lambda>
    self.properties.sort(key=lambda p: p.get_color())
AttributeError: 'OtherProperty' object has no attribute 'get_color'
2019-09-13 13:38:26,749 - telegram.ext.dispatcher - ERROR - An uncaught error was raised while processing the update
Traceback (most recent call last):
  File "/usr/local/lib/python3.7/site-packages/telegram/ext/dispatcher.py", line 279, in process_update
    handler.handle_update(update, self)
  File "/usr/local/lib/python3.7/site-packages/telegram/ext/commandhandler.py", line 173, in handle_update
    return self.callback(dispatcher.bot, update, **optional_args)
  File "/Users/logan/PycharmProjects/MonopolyTelegramBot/telegram_interaction.py", line 337, in purchase_property_handler
  File "/Users/logan/PycharmProjects/MonopolyTelegramBot/monopoly.py", line 492, in purchase_property
    property_cost = property.get_cost()
  File "/Users/logan/PycharmProjects/MonopolyTelegramBot/monopoly.py", line 127, in sort_props_by_color
    self.properties.sort(key=lambda p: p.get_color())
  File "/Users/logan/PycharmProjects/MonopolyTelegramBot/monopoly.py", line 127, in <lambda>
    self.properties.sort(key=lambda p: p.get_color())
AttributeError: 'OtherProperty' object has no attribute 'get_color'
2019-09-13 13:45:57,164 - telegram.ext.dispatcher - ERROR - An uncaught error was raised while processing the update
Traceback (most recent call last):
  File "/usr/local/lib/python3.7/site-packages/telegram/ext/dispatcher.py", line 279, in process_update
    handler.handle_update(update, self)
  File "/usr/local/lib/python3.7/site-packages/telegram/ext/commandhandler.py", line 173, in handle_update
    return self.callback(dispatcher.bot, update, **optional_args)
  File "/Users/logan/PycharmProjects/MonopolyTelegramBot/telegram_interaction.py", line 259, in bankrupt_handler
  File "/Users/logan/PycharmProjects/MonopolyTelegramBot/monopoly.py", line 1258, in bankrupt
    if type(p) == OtherProperty and p.get_type() == "Railroad":
  File "/Users/logan/PycharmProjects/MonopolyTelegramBot/monopoly.py", line 816, in trade
    return
AttributeError: 'Player' object has no attribute 'add_get_out_free_card'
2019-09-13 13:54:22,093 - telegram.ext.updater - INFO - Received signal 2 (SIGINT), stopping...
